[2024-11-16T22:16:19.323+0000] {local_task_job_runner.py:123} INFO - ::group::Pre task execution logs
[2024-11-16T22:16:19.337+0000] {taskinstance.py:2612} INFO - Dependencies all met for dep_context=non-requeueable deps ti=<TaskInstance: Ciril_group.create-db manual__2024-11-16T22:16:18.164887+00:00 [queued]>
[2024-11-16T22:16:19.344+0000] {taskinstance.py:2612} INFO - Dependencies all met for dep_context=requeueable deps ti=<TaskInstance: Ciril_group.create-db manual__2024-11-16T22:16:18.164887+00:00 [queued]>
[2024-11-16T22:16:19.344+0000] {taskinstance.py:2865} INFO - Starting attempt 1 of 6
[2024-11-16T22:16:19.357+0000] {taskinstance.py:2888} INFO - Executing <Task(BashOperator): create-db> on 2024-11-16 22:16:18.164887+00:00
[2024-11-16T22:16:19.364+0000] {standard_task_runner.py:104} INFO - Running: ['***', 'tasks', 'run', 'Ciril_group', 'create-db', 'manual__2024-11-16T22:16:18.164887+00:00', '--job-id', '9', '--raw', '--subdir', 'DAGS_FOLDER/ciril_group_dag.py', '--cfg-path', '/tmp/tmpuo9iml48']
[2024-11-16T22:16:19.367+0000] {standard_task_runner.py:105} INFO - Job 9: Subtask create-db
[2024-11-16T22:16:19.370+0000] {logging_mixin.py:190} WARNING - /home/***/.local/lib/python3.12/site-packages/***/task/task_runner/standard_task_runner.py:70 DeprecationWarning: This process (pid=186) is multi-threaded, use of fork() may lead to deadlocks in the child.
[2024-11-16T22:16:19.371+0000] {standard_task_runner.py:72} INFO - Started process 187 to run task
[2024-11-16T22:16:19.404+0000] {task_command.py:467} INFO - Running <TaskInstance: Ciril_group.create-db manual__2024-11-16T22:16:18.164887+00:00 [running]> on host 473c7a96b1b4
[2024-11-16T22:16:19.470+0000] {taskinstance.py:3131} INFO - Exporting env vars: AIRFLOW_CTX_DAG_OWNER='Simo' AIRFLOW_CTX_DAG_ID='Ciril_group' AIRFLOW_CTX_TASK_ID='create-db' AIRFLOW_CTX_EXECUTION_DATE='2024-11-16T22:16:18.164887+00:00' AIRFLOW_CTX_TRY_NUMBER='1' AIRFLOW_CTX_DAG_RUN_ID='manual__2024-11-16T22:16:18.164887+00:00'
[2024-11-16T22:16:19.471+0000] {taskinstance.py:731} INFO - ::endgroup::
[2024-11-16T22:16:19.484+0000] {subprocess.py:63} INFO - Tmp dir root location: /tmp
[2024-11-16T22:16:19.485+0000] {subprocess.py:75} INFO - Running command: ['/usr/bin/bash', '-c', '/opt/***/create-ciril-db.sh']
[2024-11-16T22:16:19.495+0000] {subprocess.py:86} INFO - Output:
[2024-11-16T22:16:19.498+0000] {subprocess.py:93} INFO - Error: SQL file 'example_schema.sql' not found!
[2024-11-16T22:16:19.499+0000] {subprocess.py:97} INFO - Command exited with return code 1
[2024-11-16T22:16:19.508+0000] {taskinstance.py:3310} ERROR - Task failed with exception
Traceback (most recent call last):
  File "/home/airflow/.local/lib/python3.12/site-packages/airflow/models/taskinstance.py", line 767, in _execute_task
    result = _execute_callable(context=context, **execute_callable_kwargs)
             ^^^^^^^^^^^^^^^^^^^^^^^^^^^^^^^^^^^^^^^^^^^^^^^^^^^^^^^^^^^^^
  File "/home/airflow/.local/lib/python3.12/site-packages/airflow/models/taskinstance.py", line 733, in _execute_callable
    return ExecutionCallableRunner(
           ^^^^^^^^^^^^^^^^^^^^^^^^
  File "/home/airflow/.local/lib/python3.12/site-packages/airflow/utils/operator_helpers.py", line 252, in run
    return self.func(*args, **kwargs)
           ^^^^^^^^^^^^^^^^^^^^^^^^^^
  File "/home/airflow/.local/lib/python3.12/site-packages/airflow/models/baseoperator.py", line 406, in wrapper
    return func(self, *args, **kwargs)
           ^^^^^^^^^^^^^^^^^^^^^^^^^^^
  File "/home/airflow/.local/lib/python3.12/site-packages/airflow/operators/bash.py", line 249, in execute
    raise AirflowException(
airflow.exceptions.AirflowException: Bash command failed. The command returned a non-zero exit code 1.
[2024-11-16T22:16:19.518+0000] {taskinstance.py:1225} INFO - Marking task as UP_FOR_RETRY. dag_id=Ciril_group, task_id=create-db, run_id=manual__2024-11-16T22:16:18.164887+00:00, execution_date=20241116T221618, start_date=20241116T221619, end_date=20241116T221619
[2024-11-16T22:16:19.720+0000] {taskinstance.py:340} INFO - ::group::Post task execution logs
[2024-11-16T22:16:19.721+0000] {standard_task_runner.py:124} ERROR - Failed to execute job 9 for task create-db (Bash command failed. The command returned a non-zero exit code 1.; 187)
Traceback (most recent call last):
  File "/home/airflow/.local/lib/python3.12/site-packages/airflow/task/task_runner/standard_task_runner.py", line 117, in _start_by_fork
    ret = args.func(args, dag=self.dag)
          ^^^^^^^^^^^^^^^^^^^^^^^^^^^^^
  File "/home/airflow/.local/lib/python3.12/site-packages/airflow/cli/cli_config.py", line 49, in command
    return func(*args, **kwargs)
           ^^^^^^^^^^^^^^^^^^^^^
  File "/home/airflow/.local/lib/python3.12/site-packages/airflow/utils/cli.py", line 115, in wrapper
    return f(*args, **kwargs)
           ^^^^^^^^^^^^^^^^^^
  File "/home/airflow/.local/lib/python3.12/site-packages/airflow/cli/commands/task_command.py", line 483, in task_run
    task_return_code = _run_task_by_selected_method(args, _dag, ti)
                       ^^^^^^^^^^^^^^^^^^^^^^^^^^^^^^^^^^^^^^^^^^^^
  File "/home/airflow/.local/lib/python3.12/site-packages/airflow/cli/commands/task_command.py", line 256, in _run_task_by_selected_method
    return _run_raw_task(args, ti)
           ^^^^^^^^^^^^^^^^^^^^^^^
  File "/home/airflow/.local/lib/python3.12/site-packages/airflow/cli/commands/task_command.py", line 341, in _run_raw_task
    return ti._run_raw_task(
           ^^^^^^^^^^^^^^^^^
  File "/home/airflow/.local/lib/python3.12/site-packages/airflow/utils/session.py", line 97, in wrapper
    return func(*args, session=session, **kwargs)
           ^^^^^^^^^^^^^^^^^^^^^^^^^^^^^^^^^^^^^^
  File "/home/airflow/.local/lib/python3.12/site-packages/airflow/models/taskinstance.py", line 3004, in _run_raw_task
    return _run_raw_task(
           ^^^^^^^^^^^^^^
  File "/home/airflow/.local/lib/python3.12/site-packages/airflow/models/taskinstance.py", line 273, in _run_raw_task
    TaskInstance._execute_task_with_callbacks(
  File "/home/airflow/.local/lib/python3.12/site-packages/airflow/models/taskinstance.py", line 3158, in _execute_task_with_callbacks
    result = self._execute_task(context, task_orig)
             ^^^^^^^^^^^^^^^^^^^^^^^^^^^^^^^^^^^^^^
  File "/home/airflow/.local/lib/python3.12/site-packages/airflow/models/taskinstance.py", line 3182, in _execute_task
    return _execute_task(self, context, task_orig)
           ^^^^^^^^^^^^^^^^^^^^^^^^^^^^^^^^^^^^^^^
  File "/home/airflow/.local/lib/python3.12/site-packages/airflow/models/taskinstance.py", line 767, in _execute_task
    result = _execute_callable(context=context, **execute_callable_kwargs)
             ^^^^^^^^^^^^^^^^^^^^^^^^^^^^^^^^^^^^^^^^^^^^^^^^^^^^^^^^^^^^^
  File "/home/airflow/.local/lib/python3.12/site-packages/airflow/models/taskinstance.py", line 733, in _execute_callable
    return ExecutionCallableRunner(
           ^^^^^^^^^^^^^^^^^^^^^^^^
  File "/home/airflow/.local/lib/python3.12/site-packages/airflow/utils/operator_helpers.py", line 252, in run
    return self.func(*args, **kwargs)
           ^^^^^^^^^^^^^^^^^^^^^^^^^^
  File "/home/airflow/.local/lib/python3.12/site-packages/airflow/models/baseoperator.py", line 406, in wrapper
    return func(self, *args, **kwargs)
           ^^^^^^^^^^^^^^^^^^^^^^^^^^^
  File "/home/airflow/.local/lib/python3.12/site-packages/airflow/operators/bash.py", line 249, in execute
    raise AirflowException(
airflow.exceptions.AirflowException: Bash command failed. The command returned a non-zero exit code 1.
[2024-11-16T22:16:19.746+0000] {local_task_job_runner.py:266} INFO - Task exited with return code 1
[2024-11-16T22:16:19.755+0000] {local_task_job_runner.py:245} INFO - ::endgroup::
