[2024-11-16T19:05:14.090+0000] {local_task_job_runner.py:123} INFO - ::group::Pre task execution logs
[2024-11-16T19:05:14.104+0000] {taskinstance.py:2612} INFO - Dependencies all met for dep_context=non-requeueable deps ti=<TaskInstance: Ciril_group.run-example manual__2024-11-16T18:38:01.197779+00:00 [queued]>
[2024-11-16T19:05:14.111+0000] {taskinstance.py:2612} INFO - Dependencies all met for dep_context=requeueable deps ti=<TaskInstance: Ciril_group.run-example manual__2024-11-16T18:38:01.197779+00:00 [queued]>
[2024-11-16T19:05:14.111+0000] {taskinstance.py:2865} INFO - Starting attempt 6 of 6
[2024-11-16T19:05:14.122+0000] {taskinstance.py:2888} INFO - Executing <Task(DockerOperator): run-example> on 2024-11-16 18:38:01.197779+00:00
[2024-11-16T19:05:14.129+0000] {standard_task_runner.py:104} INFO - Running: ['***', 'tasks', 'run', 'Ciril_group', 'run-example', 'manual__2024-11-16T18:38:01.197779+00:00', '--job-id', '42', '--raw', '--subdir', 'DAGS_FOLDER/ciril_group_dag.py', '--cfg-path', '/tmp/tmp3r0la1bd']
[2024-11-16T19:05:14.131+0000] {standard_task_runner.py:105} INFO - Job 42: Subtask run-example
[2024-11-16T19:05:14.134+0000] {logging_mixin.py:190} WARNING - /home/***/.local/lib/python3.12/site-packages/***/task/task_runner/standard_task_runner.py:70 DeprecationWarning: This process (pid=365) is multi-threaded, use of fork() may lead to deadlocks in the child.
[2024-11-16T19:05:14.135+0000] {standard_task_runner.py:72} INFO - Started process 366 to run task
[2024-11-16T19:05:14.166+0000] {task_command.py:467} INFO - Running <TaskInstance: Ciril_group.run-example manual__2024-11-16T18:38:01.197779+00:00 [running]> on host 5a65a9f2dbfb
[2024-11-16T19:05:14.226+0000] {taskinstance.py:3131} INFO - Exporting env vars: AIRFLOW_CTX_DAG_OWNER='Simo' AIRFLOW_CTX_DAG_ID='Ciril_group' AIRFLOW_CTX_TASK_ID='run-example' AIRFLOW_CTX_EXECUTION_DATE='2024-11-16T18:38:01.197779+00:00' AIRFLOW_CTX_TRY_NUMBER='6' AIRFLOW_CTX_DAG_RUN_ID='manual__2024-11-16T18:38:01.197779+00:00'
[2024-11-16T19:05:14.226+0000] {taskinstance.py:731} INFO - ::endgroup::
[2024-11-16T19:05:14.266+0000] {docker.py:367} INFO - Starting docker container from image ***_ciril:latest
[2024-11-16T19:05:20.858+0000] {docker.py:438} INFO - 
[2024-11-16T19:05:20.882+0000] {docker.py:438} INFO - python: can't open file '/opt/***/image-python/example.py': [Errno 2] No such file or directory
[2024-11-16T19:05:21.250+0000] {taskinstance.py:3310} ERROR - Task failed with exception
Traceback (most recent call last):
  File "/home/airflow/.local/lib/python3.12/site-packages/airflow/models/taskinstance.py", line 767, in _execute_task
    result = _execute_callable(context=context, **execute_callable_kwargs)
             ^^^^^^^^^^^^^^^^^^^^^^^^^^^^^^^^^^^^^^^^^^^^^^^^^^^^^^^^^^^^^
  File "/home/airflow/.local/lib/python3.12/site-packages/airflow/models/taskinstance.py", line 733, in _execute_callable
    return ExecutionCallableRunner(
           ^^^^^^^^^^^^^^^^^^^^^^^^
  File "/home/airflow/.local/lib/python3.12/site-packages/airflow/utils/operator_helpers.py", line 252, in run
    return self.func(*args, **kwargs)
           ^^^^^^^^^^^^^^^^^^^^^^^^^^
  File "/home/airflow/.local/lib/python3.12/site-packages/airflow/models/baseoperator.py", line 406, in wrapper
    return func(self, *args, **kwargs)
           ^^^^^^^^^^^^^^^^^^^^^^^^^^^
  File "/home/airflow/.local/lib/python3.12/site-packages/airflow/providers/docker/operators/docker.py", line 513, in execute
    return self._run_image()
           ^^^^^^^^^^^^^^^^^
  File "/home/airflow/.local/lib/python3.12/site-packages/airflow/providers/docker/operators/docker.py", line 372, in _run_image
    return self._run_image_with_mounts([*self.mounts, tmp_mount], add_tmp_variable=True)
           ^^^^^^^^^^^^^^^^^^^^^^^^^^^^^^^^^^^^^^^^^^^^^^^^^^^^^^^^^^^^^^^^^^^^^^^^^^^^^
  File "/home/airflow/.local/lib/python3.12/site-packages/airflow/providers/docker/operators/docker.py", line 446, in _run_image_with_mounts
    raise DockerContainerFailedException(f"Docker container failed: {result!r}", logs=log_lines)
airflow.providers.docker.exceptions.DockerContainerFailedException: Docker container failed: {'StatusCode': 2}
[2024-11-16T19:05:21.253+0000] {taskinstance.py:1225} INFO - Marking task as FAILED. dag_id=Ciril_group, task_id=run-example, run_id=manual__2024-11-16T18:38:01.197779+00:00, execution_date=20241116T183801, start_date=20241116T190514, end_date=20241116T190521
[2024-11-16T19:05:21.398+0000] {taskinstance.py:340} INFO - ::group::Post task execution logs
[2024-11-16T19:05:21.399+0000] {standard_task_runner.py:124} ERROR - Failed to execute job 42 for task run-example (Docker container failed: {'StatusCode': 2}; 366)
Traceback (most recent call last):
  File "/home/airflow/.local/lib/python3.12/site-packages/airflow/task/task_runner/standard_task_runner.py", line 117, in _start_by_fork
    ret = args.func(args, dag=self.dag)
          ^^^^^^^^^^^^^^^^^^^^^^^^^^^^^
  File "/home/airflow/.local/lib/python3.12/site-packages/airflow/cli/cli_config.py", line 49, in command
    return func(*args, **kwargs)
           ^^^^^^^^^^^^^^^^^^^^^
  File "/home/airflow/.local/lib/python3.12/site-packages/airflow/utils/cli.py", line 115, in wrapper
    return f(*args, **kwargs)
           ^^^^^^^^^^^^^^^^^^
  File "/home/airflow/.local/lib/python3.12/site-packages/airflow/cli/commands/task_command.py", line 483, in task_run
    task_return_code = _run_task_by_selected_method(args, _dag, ti)
                       ^^^^^^^^^^^^^^^^^^^^^^^^^^^^^^^^^^^^^^^^^^^^
  File "/home/airflow/.local/lib/python3.12/site-packages/airflow/cli/commands/task_command.py", line 256, in _run_task_by_selected_method
    return _run_raw_task(args, ti)
           ^^^^^^^^^^^^^^^^^^^^^^^
  File "/home/airflow/.local/lib/python3.12/site-packages/airflow/cli/commands/task_command.py", line 341, in _run_raw_task
    return ti._run_raw_task(
           ^^^^^^^^^^^^^^^^^
  File "/home/airflow/.local/lib/python3.12/site-packages/airflow/utils/session.py", line 97, in wrapper
    return func(*args, session=session, **kwargs)
           ^^^^^^^^^^^^^^^^^^^^^^^^^^^^^^^^^^^^^^
  File "/home/airflow/.local/lib/python3.12/site-packages/airflow/models/taskinstance.py", line 3004, in _run_raw_task
    return _run_raw_task(
           ^^^^^^^^^^^^^^
  File "/home/airflow/.local/lib/python3.12/site-packages/airflow/models/taskinstance.py", line 273, in _run_raw_task
    TaskInstance._execute_task_with_callbacks(
  File "/home/airflow/.local/lib/python3.12/site-packages/airflow/models/taskinstance.py", line 3158, in _execute_task_with_callbacks
    result = self._execute_task(context, task_orig)
             ^^^^^^^^^^^^^^^^^^^^^^^^^^^^^^^^^^^^^^
  File "/home/airflow/.local/lib/python3.12/site-packages/airflow/models/taskinstance.py", line 3182, in _execute_task
    return _execute_task(self, context, task_orig)
           ^^^^^^^^^^^^^^^^^^^^^^^^^^^^^^^^^^^^^^^
  File "/home/airflow/.local/lib/python3.12/site-packages/airflow/models/taskinstance.py", line 767, in _execute_task
    result = _execute_callable(context=context, **execute_callable_kwargs)
             ^^^^^^^^^^^^^^^^^^^^^^^^^^^^^^^^^^^^^^^^^^^^^^^^^^^^^^^^^^^^^
  File "/home/airflow/.local/lib/python3.12/site-packages/airflow/models/taskinstance.py", line 733, in _execute_callable
    return ExecutionCallableRunner(
           ^^^^^^^^^^^^^^^^^^^^^^^^
  File "/home/airflow/.local/lib/python3.12/site-packages/airflow/utils/operator_helpers.py", line 252, in run
    return self.func(*args, **kwargs)
           ^^^^^^^^^^^^^^^^^^^^^^^^^^
  File "/home/airflow/.local/lib/python3.12/site-packages/airflow/models/baseoperator.py", line 406, in wrapper
    return func(self, *args, **kwargs)
           ^^^^^^^^^^^^^^^^^^^^^^^^^^^
  File "/home/airflow/.local/lib/python3.12/site-packages/airflow/providers/docker/operators/docker.py", line 513, in execute
    return self._run_image()
           ^^^^^^^^^^^^^^^^^
  File "/home/airflow/.local/lib/python3.12/site-packages/airflow/providers/docker/operators/docker.py", line 372, in _run_image
    return self._run_image_with_mounts([*self.mounts, tmp_mount], add_tmp_variable=True)
           ^^^^^^^^^^^^^^^^^^^^^^^^^^^^^^^^^^^^^^^^^^^^^^^^^^^^^^^^^^^^^^^^^^^^^^^^^^^^^
  File "/home/airflow/.local/lib/python3.12/site-packages/airflow/providers/docker/operators/docker.py", line 446, in _run_image_with_mounts
    raise DockerContainerFailedException(f"Docker container failed: {result!r}", logs=log_lines)
airflow.providers.docker.exceptions.DockerContainerFailedException: Docker container failed: {'StatusCode': 2}
[2024-11-16T19:05:21.412+0000] {local_task_job_runner.py:266} INFO - Task exited with return code 1
[2024-11-16T19:05:21.431+0000] {taskinstance.py:3900} INFO - 0 downstream tasks scheduled from follow-on schedule check
[2024-11-16T19:05:21.434+0000] {local_task_job_runner.py:245} INFO - ::endgroup::
