[2024-11-16T21:48:36.701+0000] {local_task_job_runner.py:123} INFO - ::group::Pre task execution logs
[2024-11-16T21:48:36.718+0000] {taskinstance.py:2612} INFO - Dependencies all met for dep_context=non-requeueable deps ti=<TaskInstance: Ciril_group.load_to_db manual__2024-11-16T21:48:25.418896+00:00 [queued]>
[2024-11-16T21:48:36.726+0000] {taskinstance.py:2612} INFO - Dependencies all met for dep_context=requeueable deps ti=<TaskInstance: Ciril_group.load_to_db manual__2024-11-16T21:48:25.418896+00:00 [queued]>
[2024-11-16T21:48:36.727+0000] {taskinstance.py:2865} INFO - Starting attempt 1 of 6
[2024-11-16T21:48:36.739+0000] {taskinstance.py:2888} INFO - Executing <Task(DockerOperator): load_to_db> on 2024-11-16 21:48:25.418896+00:00
[2024-11-16T21:48:36.746+0000] {standard_task_runner.py:104} INFO - Running: ['***', 'tasks', 'run', 'Ciril_group', 'load_to_db', 'manual__2024-11-16T21:48:25.418896+00:00', '--job-id', '28', '--raw', '--subdir', 'DAGS_FOLDER/ciril_group_dag.py', '--cfg-path', '/tmp/tmpw778ewwt']
[2024-11-16T21:48:36.748+0000] {standard_task_runner.py:105} INFO - Job 28: Subtask load_to_db
[2024-11-16T21:48:36.751+0000] {logging_mixin.py:190} WARNING - /home/***/.local/lib/python3.12/site-packages/***/task/task_runner/standard_task_runner.py:70 DeprecationWarning: This process (pid=208) is multi-threaded, use of fork() may lead to deadlocks in the child.
[2024-11-16T21:48:36.752+0000] {standard_task_runner.py:72} INFO - Started process 209 to run task
[2024-11-16T21:48:36.787+0000] {task_command.py:467} INFO - Running <TaskInstance: Ciril_group.load_to_db manual__2024-11-16T21:48:25.418896+00:00 [running]> on host 18bedcadc166
[2024-11-16T21:48:36.852+0000] {taskinstance.py:3131} INFO - Exporting env vars: AIRFLOW_CTX_DAG_OWNER='Simo' AIRFLOW_CTX_DAG_ID='Ciril_group' AIRFLOW_CTX_TASK_ID='load_to_db' AIRFLOW_CTX_EXECUTION_DATE='2024-11-16T21:48:25.418896+00:00' AIRFLOW_CTX_TRY_NUMBER='1' AIRFLOW_CTX_DAG_RUN_ID='manual__2024-11-16T21:48:25.418896+00:00'
[2024-11-16T21:48:36.853+0000] {taskinstance.py:731} INFO - ::endgroup::
[2024-11-16T21:48:36.897+0000] {docker.py:367} INFO - Starting docker container from image ***_ciril:latest
[2024-11-16T21:48:43.546+0000] {docker.py:438} INFO - 
[2024-11-16T21:48:44.104+0000] {docker.py:438} INFO - /opt/***/load-csv/load_to_db.py:13: RemovedIn20Warning: [31mDeprecated API features detected! These feature(s) are not compatible with SQLAlchemy 2.0. [32mTo prevent incompatible upgrades prior to updating applications, ensure requirements files are pinned to "sqlalchemy<2.0". [36mSet environment variable SQLALCHEMY_WARN_20=1 to show all deprecation warnings.  Set environment variable SQLALCHEMY_SILENCE_UBER_WARNING=1 to silence this message.[0m (Background on SQLAlchemy 2.0 at: https://sqlalche.me/e/b8d9)
[2024-11-16T21:48:44.104+0000] {docker.py:438} INFO -   metadata = sqlalchemy.schema.MetaData(engine)
[2024-11-16T21:48:44.105+0000] {docker.py:438} INFO - Connexion Ã  la base de donnÃ©es rÃ©ussie
[2024-11-16T21:48:44.115+0000] {docker.py:438} INFO - Traceback (most recent call last):
[2024-11-16T21:48:44.116+0000] {docker.py:438} INFO -   File "/home/***/.local/lib/python3.12/site-packages/sqlalchemy/engine/base.py", line 1910, in _execute_context
[2024-11-16T21:48:44.116+0000] {docker.py:438} INFO - self.dialect.do_execute(
[2024-11-16T21:48:44.117+0000] {docker.py:438} INFO -   File "/home/***/.local/lib/python3.12/site-packages/sqlalchemy/engine/default.py", line 736, in do_execute
[2024-11-16T21:48:44.118+0000] {docker.py:438} INFO -     cursor.execute(statement, parameters)
[2024-11-16T21:48:44.119+0000] {docker.py:438} INFO -   File "/home/***/.local/lib/python3.12/site-packages/MySQLdb/cursors.py", line 206, in execute
[2024-11-16T21:48:44.119+0000] {docker.py:438} INFO -     res = self._query(query)
[2024-11-16T21:48:44.119+0000] {docker.py:438} INFO -           ^^^^^^^^^^^^^^^^^^
[2024-11-16T21:48:44.120+0000] {docker.py:438} INFO -   File "/home/***/.local/lib/python3.12/site-packages/MySQLdb/cursors.py", line 319, in _query
[2024-11-16T21:48:44.120+0000] {docker.py:438} INFO -     db.query(q)
[2024-11-16T21:48:44.121+0000] {docker.py:438} INFO -   File "/home/***/.local/lib/python3.12/site-packages/MySQLdb/connections.py", line 254, in query
[2024-11-16T21:48:44.121+0000] {docker.py:438} INFO -     _mysql.connection.query(self, query)
[2024-11-16T21:48:44.122+0000] {docker.py:438} INFO - MySQLdb.ProgrammingError: (1146, "Table 'db_dteng.places' doesn't exist")
[2024-11-16T21:48:44.122+0000] {docker.py:438} INFO - 
[2024-11-16T21:48:44.123+0000] {docker.py:438} INFO - The above exception was the direct cause of the following exception:
[2024-11-16T21:48:44.123+0000] {docker.py:438} INFO - 
[2024-11-16T21:48:44.124+0000] {docker.py:438} INFO - Traceback (most recent call last):
[2024-11-16T21:48:44.124+0000] {docker.py:438} INFO -   File "/home/***/.local/lib/python3.12/site-packages/sqlalchemy/dialects/mysql/base.py", line 3220, in _show_create_table
[2024-11-16T21:48:44.124+0000] {docker.py:438} INFO - ).exec_driver_sql(st)
[2024-11-16T21:48:44.125+0000] {docker.py:438} INFO -       ^^^^^^^^^^^^^^^^^^^
[2024-11-16T21:48:44.125+0000] {docker.py:438} INFO -   File "/home/***/.local/lib/python3.12/site-packages/sqlalchemy/engine/base.py", line 1770, in exec_driver_sql
[2024-11-16T21:48:44.126+0000] {docker.py:438} INFO -     return self._exec_driver_sql(
[2024-11-16T21:48:44.126+0000] {docker.py:438} INFO -            ^^^^^^^^^^^^^^^^^^^^^^
[2024-11-16T21:48:44.127+0000] {docker.py:438} INFO -   File "/home/***/.local/lib/python3.12/site-packages/sqlalchemy/engine/base.py", line 1674, in _exec_driver_sql
[2024-11-16T21:48:44.127+0000] {docker.py:438} INFO -     ret = self._execute_context(
[2024-11-16T21:48:44.127+0000] {docker.py:438} INFO -           ^^^^^^^^^^^^^^^^^^^^^^
[2024-11-16T21:48:44.128+0000] {docker.py:438} INFO -   File "/home/***/.local/lib/python3.12/site-packages/sqlalchemy/engine/base.py", line 1953, in _execute_context
[2024-11-16T21:48:44.128+0000] {docker.py:438} INFO -     self._handle_dbapi_exception(
[2024-11-16T21:48:44.129+0000] {docker.py:438} INFO -   File "/home/***/.local/lib/python3.12/site-packages/sqlalchemy/engine/base.py", line 2134, in _handle_dbapi_exception
[2024-11-16T21:48:44.129+0000] {docker.py:438} INFO -     util.raise_(
[2024-11-16T21:48:44.130+0000] {docker.py:438} INFO -   File "/home/***/.local/lib/python3.12/site-packages/sqlalchemy/util/compat.py", line 211, in raise_
[2024-11-16T21:48:44.131+0000] {docker.py:438} INFO -     raise exception
[2024-11-16T21:48:44.131+0000] {docker.py:438} INFO -   File "/home/***/.local/lib/python3.12/site-packages/sqlalchemy/engine/base.py", line 1910, in _execute_context
[2024-11-16T21:48:44.132+0000] {docker.py:438} INFO -     self.dialect.do_execute(
[2024-11-16T21:48:44.132+0000] {docker.py:438} INFO -   File "/home/***/.local/lib/python3.12/site-packages/sqlalchemy/engine/default.py", line 736, in do_execute
[2024-11-16T21:48:44.133+0000] {docker.py:438} INFO -     cursor.execute(statement, parameters)
[2024-11-16T21:48:44.133+0000] {docker.py:438} INFO -   File "/home/***/.local/lib/python3.12/site-packages/MySQLdb/cursors.py", line 206, in execute
[2024-11-16T21:48:44.134+0000] {docker.py:438} INFO -     res = self._query(query)
[2024-11-16T21:48:44.134+0000] {docker.py:438} INFO -           ^^^^^^^^^^^^^^^^^^
[2024-11-16T21:48:44.135+0000] {docker.py:438} INFO -   File "/home/***/.local/lib/python3.12/site-packages/MySQLdb/cursors.py", line 319, in _query
[2024-11-16T21:48:44.135+0000] {docker.py:438} INFO -     db.query(q)
[2024-11-16T21:48:44.136+0000] {docker.py:438} INFO -   File "/home/***/.local/lib/python3.12/site-packages/MySQLdb/connections.py", line 254, in query
[2024-11-16T21:48:44.136+0000] {docker.py:438} INFO -     _mysql.connection.query(self, query)
[2024-11-16T21:48:44.137+0000] {docker.py:438} INFO - sqlalchemy.exc.ProgrammingError: (MySQLdb.ProgrammingError) (1146, "Table 'db_dteng.places' doesn't exist")
[2024-11-16T21:48:44.137+0000] {docker.py:438} INFO - [SQL: SHOW CREATE TABLE `places`]
[2024-11-16T21:48:44.138+0000] {docker.py:438} INFO - (Background on this error at: https://sqlalche.me/e/14/f405)
[2024-11-16T21:48:44.138+0000] {docker.py:438} INFO - 
[2024-11-16T21:48:44.139+0000] {docker.py:438} INFO - The above exception was the direct cause of the following exception:
[2024-11-16T21:48:44.139+0000] {docker.py:438} INFO - 
[2024-11-16T21:48:44.139+0000] {docker.py:438} INFO - Traceback (most recent call last):
[2024-11-16T21:48:44.140+0000] {docker.py:438} INFO -   File "/opt/***/load-csv/load_to_db.py", line 23, in <module>
[2024-11-16T21:48:44.140+0000] {docker.py:438} INFO -     Places=   sqlalchemy.schema.Table('places', metadata, autoload=True, autoload_with=engine)
[2024-11-16T21:48:44.141+0000] {docker.py:438} INFO -               ^^^^^^^^^^^^^^^^^^^^^^^^^^^^^^^^^^^^^^^^^^^^^^^^^^^^^^^^^^^^^^^^^^^^^^^^^^^^^^^^
[2024-11-16T21:48:44.141+0000] {docker.py:438} INFO -   File "<string>", line 2, in __new__
[2024-11-16T21:48:44.141+0000] {docker.py:438} INFO -   File "/home/***/.local/lib/python3.12/site-packages/sqlalchemy/util/deprecations.py", line 375, in warned
[2024-11-16T21:48:44.142+0000] {docker.py:438} INFO -     return fn(*args, **kwargs)
[2024-11-16T21:48:44.142+0000] {docker.py:438} INFO -            ^^^^^^^^^^^^^^^^^^^
[2024-11-16T21:48:44.143+0000] {docker.py:438} INFO -   File "/home/***/.local/lib/python3.12/site-packages/sqlalchemy/sql/schema.py", line 618, in __new__
[2024-11-16T21:48:44.143+0000] {docker.py:438} INFO -     with util.safe_reraise():
[2024-11-16T21:48:44.144+0000] {docker.py:438} INFO -          ^^^^^^^^^^^^^^^^^^^
[2024-11-16T21:48:44.144+0000] {docker.py:438} INFO -   File "/home/***/.local/lib/python3.12/site-packages/sqlalchemy/util/langhelpers.py", line 70, in __exit__
[2024-11-16T21:48:44.145+0000] {docker.py:438} INFO -     compat.raise_(
[2024-11-16T21:48:44.145+0000] {docker.py:438} INFO -   File "/home/***/.local/lib/python3.12/site-packages/sqlalchemy/util/compat.py", line 211, in raise_
[2024-11-16T21:48:44.146+0000] {docker.py:438} INFO -     raise exception
[2024-11-16T21:48:44.146+0000] {docker.py:438} INFO -   File "/home/***/.local/lib/python3.12/site-packages/sqlalchemy/sql/schema.py", line 614, in __new__
[2024-11-16T21:48:44.147+0000] {docker.py:438} INFO -     table._init(name, metadata, *args, **kw)
[2024-11-16T21:48:44.147+0000] {docker.py:438} INFO -   File "/home/***/.local/lib/python3.12/site-packages/sqlalchemy/sql/schema.py", line 689, in _init
[2024-11-16T21:48:44.147+0000] {docker.py:438} INFO -     self._autoload(
[2024-11-16T21:48:44.148+0000] {docker.py:438} INFO -   File "/home/***/.local/lib/python3.12/site-packages/sqlalchemy/sql/schema.py", line 724, in _autoload
[2024-11-16T21:48:44.148+0000] {docker.py:438} INFO -     conn_insp.reflect_table(
[2024-11-16T21:48:44.149+0000] {docker.py:438} INFO -   File "/home/***/.local/lib/python3.12/site-packages/sqlalchemy/engine/reflection.py", line 757, in reflect_table
[2024-11-16T21:48:44.150+0000] {docker.py:438} INFO -     tbl_opts = self.get_table_options(
[2024-11-16T21:48:44.150+0000] {docker.py:438} INFO -                ^^^^^^^^^^^^^^^^^^^^^^^
[2024-11-16T21:48:44.151+0000] {docker.py:438} INFO -   File "/home/***/.local/lib/python3.12/site-packages/sqlalchemy/engine/reflection.py", line 398, in get_table_options
[2024-11-16T21:48:44.151+0000] {docker.py:438} INFO -     return self.dialect.get_table_options(
[2024-11-16T21:48:44.152+0000] {docker.py:438} INFO -            ^^^^^^^^^^^^^^^^^^^^^^^^^^^^^^^
[2024-11-16T21:48:44.153+0000] {docker.py:438} INFO -   File "<string>", line 2, in get_table_options
[2024-11-16T21:48:44.153+0000] {docker.py:438} INFO -   File "/home/***/.local/lib/python3.12/site-packages/sqlalchemy/engine/reflection.py", line 55, in cache
[2024-11-16T21:48:44.154+0000] {docker.py:438} INFO -     ret = fn(self, con, *args, **kw)
[2024-11-16T21:48:44.154+0000] {docker.py:438} INFO -           ^^^^^^^^^^^^^^^^^^^^^^^^^^
[2024-11-16T21:48:44.154+0000] {docker.py:438} INFO -   File "/home/***/.local/lib/python3.12/site-packages/sqlalchemy/dialects/mysql/base.py", line 2828, in get_table_options
[2024-11-16T21:48:44.155+0000] {docker.py:438} INFO -     parsed_state = self._parsed_state_or_create(
[2024-11-16T21:48:44.155+0000] {docker.py:438} INFO -                    ^^^^^^^^^^^^^^^^^^^^^^^^^^^^^
[2024-11-16T21:48:44.156+0000] {docker.py:438} INFO -   F
[2024-11-16T21:48:44.156+0000] {docker.py:438} INFO - ile "/home/***/.local/lib/python3.12/site-packages/sqlalchemy/dialects/mysql/base.py", line 3085, in _parsed_state_or_create
[2024-11-16T21:48:44.157+0000] {docker.py:438} INFO -     return self._setup_parser(
[2024-11-16T21:48:44.157+0000] {docker.py:438} INFO -            ^^^^^^^^^^^^^^^^^^^
[2024-11-16T21:48:44.158+0000] {docker.py:438} INFO -   File "<string>", line 2, in _setup_parser
[2024-11-16T21:48:44.158+0000] {docker.py:438} INFO -   File "/home/***/.local/lib/python3.12/site-packages/sqlalchemy/engine/reflection.py", line 55, in cache
[2024-11-16T21:48:44.159+0000] {docker.py:438} INFO -     ret = fn(self, con, *args, **kw)
[2024-11-16T21:48:44.159+0000] {docker.py:438} INFO -           ^^^^^^^^^^^^^^^^^^^^^^^^^^
[2024-11-16T21:48:44.160+0000] {docker.py:438} INFO -   File "/home/***/.local/lib/python3.12/site-packages/sqlalchemy/dialects/mysql/base.py", line 3112, in _setup_parser
[2024-11-16T21:48:44.160+0000] {docker.py:438} INFO -     sql = self._show_create_table(
[2024-11-16T21:48:44.161+0000] {docker.py:438} INFO -           ^^^^^^^^^^^^^^^^^^^^^^^^
[2024-11-16T21:48:44.161+0000] {docker.py:438} INFO -   File "/home/***/.local/lib/python3.12/site-packages/sqlalchemy/dialects/mysql/base.py", line 3223, in _show_create_table
[2024-11-16T21:48:44.161+0000] {docker.py:438} INFO -     util.raise_(exc.NoSuchTableError(full_name), replace_context=e)
[2024-11-16T21:48:44.162+0000] {docker.py:438} INFO -   File "/home/***/.local/lib/python3.12/site-packages/sqlalchemy/util/compat.py", line 211, in raise_
[2024-11-16T21:48:44.162+0000] {docker.py:438} INFO -     raise exception
[2024-11-16T21:48:44.163+0000] {docker.py:438} INFO - sqlalchemy.exc.NoSuchTableError: `places`
[2024-11-16T21:48:44.579+0000] {taskinstance.py:3310} ERROR - Task failed with exception
Traceback (most recent call last):
  File "/home/airflow/.local/lib/python3.12/site-packages/airflow/models/taskinstance.py", line 767, in _execute_task
    result = _execute_callable(context=context, **execute_callable_kwargs)
             ^^^^^^^^^^^^^^^^^^^^^^^^^^^^^^^^^^^^^^^^^^^^^^^^^^^^^^^^^^^^^
  File "/home/airflow/.local/lib/python3.12/site-packages/airflow/models/taskinstance.py", line 733, in _execute_callable
    return ExecutionCallableRunner(
           ^^^^^^^^^^^^^^^^^^^^^^^^
  File "/home/airflow/.local/lib/python3.12/site-packages/airflow/utils/operator_helpers.py", line 252, in run
    return self.func(*args, **kwargs)
           ^^^^^^^^^^^^^^^^^^^^^^^^^^
  File "/home/airflow/.local/lib/python3.12/site-packages/airflow/models/baseoperator.py", line 406, in wrapper
    return func(self, *args, **kwargs)
           ^^^^^^^^^^^^^^^^^^^^^^^^^^^
  File "/home/airflow/.local/lib/python3.12/site-packages/airflow/providers/docker/operators/docker.py", line 513, in execute
    return self._run_image()
           ^^^^^^^^^^^^^^^^^
  File "/home/airflow/.local/lib/python3.12/site-packages/airflow/providers/docker/operators/docker.py", line 372, in _run_image
    return self._run_image_with_mounts([*self.mounts, tmp_mount], add_tmp_variable=True)
           ^^^^^^^^^^^^^^^^^^^^^^^^^^^^^^^^^^^^^^^^^^^^^^^^^^^^^^^^^^^^^^^^^^^^^^^^^^^^^
  File "/home/airflow/.local/lib/python3.12/site-packages/airflow/providers/docker/operators/docker.py", line 446, in _run_image_with_mounts
    raise DockerContainerFailedException(f"Docker container failed: {result!r}", logs=log_lines)
airflow.providers.docker.exceptions.DockerContainerFailedException: Docker container failed: {'StatusCode': 1}
[2024-11-16T21:48:44.748+0000] {taskinstance.py:1225} INFO - Marking task as UP_FOR_RETRY. dag_id=Ciril_group, task_id=load_to_db, run_id=manual__2024-11-16T21:48:25.418896+00:00, execution_date=20241116T214825, start_date=20241116T214836, end_date=20241116T214844
[2024-11-16T21:48:44.763+0000] {taskinstance.py:340} INFO - ::group::Post task execution logs
[2024-11-16T21:48:44.764+0000] {standard_task_runner.py:124} ERROR - Failed to execute job 28 for task load_to_db (Docker container failed: {'StatusCode': 1}; 209)
Traceback (most recent call last):
  File "/home/airflow/.local/lib/python3.12/site-packages/airflow/task/task_runner/standard_task_runner.py", line 117, in _start_by_fork
    ret = args.func(args, dag=self.dag)
          ^^^^^^^^^^^^^^^^^^^^^^^^^^^^^
  File "/home/airflow/.local/lib/python3.12/site-packages/airflow/cli/cli_config.py", line 49, in command
    return func(*args, **kwargs)
           ^^^^^^^^^^^^^^^^^^^^^
  File "/home/airflow/.local/lib/python3.12/site-packages/airflow/utils/cli.py", line 115, in wrapper
    return f(*args, **kwargs)
           ^^^^^^^^^^^^^^^^^^
  File "/home/airflow/.local/lib/python3.12/site-packages/airflow/cli/commands/task_command.py", line 483, in task_run
    task_return_code = _run_task_by_selected_method(args, _dag, ti)
                       ^^^^^^^^^^^^^^^^^^^^^^^^^^^^^^^^^^^^^^^^^^^^
  File "/home/airflow/.local/lib/python3.12/site-packages/airflow/cli/commands/task_command.py", line 256, in _run_task_by_selected_method
    return _run_raw_task(args, ti)
           ^^^^^^^^^^^^^^^^^^^^^^^
  File "/home/airflow/.local/lib/python3.12/site-packages/airflow/cli/commands/task_command.py", line 341, in _run_raw_task
    return ti._run_raw_task(
           ^^^^^^^^^^^^^^^^^
  File "/home/airflow/.local/lib/python3.12/site-packages/airflow/utils/session.py", line 97, in wrapper
    return func(*args, session=session, **kwargs)
           ^^^^^^^^^^^^^^^^^^^^^^^^^^^^^^^^^^^^^^
  File "/home/airflow/.local/lib/python3.12/site-packages/airflow/models/taskinstance.py", line 3004, in _run_raw_task
    return _run_raw_task(
           ^^^^^^^^^^^^^^
  File "/home/airflow/.local/lib/python3.12/site-packages/airflow/models/taskinstance.py", line 273, in _run_raw_task
    TaskInstance._execute_task_with_callbacks(
  File "/home/airflow/.local/lib/python3.12/site-packages/airflow/models/taskinstance.py", line 3158, in _execute_task_with_callbacks
    result = self._execute_task(context, task_orig)
             ^^^^^^^^^^^^^^^^^^^^^^^^^^^^^^^^^^^^^^
  File "/home/airflow/.local/lib/python3.12/site-packages/airflow/models/taskinstance.py", line 3182, in _execute_task
    return _execute_task(self, context, task_orig)
           ^^^^^^^^^^^^^^^^^^^^^^^^^^^^^^^^^^^^^^^
  File "/home/airflow/.local/lib/python3.12/site-packages/airflow/models/taskinstance.py", line 767, in _execute_task
    result = _execute_callable(context=context, **execute_callable_kwargs)
             ^^^^^^^^^^^^^^^^^^^^^^^^^^^^^^^^^^^^^^^^^^^^^^^^^^^^^^^^^^^^^
  File "/home/airflow/.local/lib/python3.12/site-packages/airflow/models/taskinstance.py", line 733, in _execute_callable
    return ExecutionCallableRunner(
           ^^^^^^^^^^^^^^^^^^^^^^^^
  File "/home/airflow/.local/lib/python3.12/site-packages/airflow/utils/operator_helpers.py", line 252, in run
    return self.func(*args, **kwargs)
           ^^^^^^^^^^^^^^^^^^^^^^^^^^
  File "/home/airflow/.local/lib/python3.12/site-packages/airflow/models/baseoperator.py", line 406, in wrapper
    return func(self, *args, **kwargs)
           ^^^^^^^^^^^^^^^^^^^^^^^^^^^
  File "/home/airflow/.local/lib/python3.12/site-packages/airflow/providers/docker/operators/docker.py", line 513, in execute
    return self._run_image()
           ^^^^^^^^^^^^^^^^^
  File "/home/airflow/.local/lib/python3.12/site-packages/airflow/providers/docker/operators/docker.py", line 372, in _run_image
    return self._run_image_with_mounts([*self.mounts, tmp_mount], add_tmp_variable=True)
           ^^^^^^^^^^^^^^^^^^^^^^^^^^^^^^^^^^^^^^^^^^^^^^^^^^^^^^^^^^^^^^^^^^^^^^^^^^^^^
  File "/home/airflow/.local/lib/python3.12/site-packages/airflow/providers/docker/operators/docker.py", line 446, in _run_image_with_mounts
    raise DockerContainerFailedException(f"Docker container failed: {result!r}", logs=log_lines)
airflow.providers.docker.exceptions.DockerContainerFailedException: Docker container failed: {'StatusCode': 1}
[2024-11-16T21:48:44.790+0000] {local_task_job_runner.py:266} INFO - Task exited with return code 1
[2024-11-16T21:48:44.800+0000] {local_task_job_runner.py:245} INFO - ::endgroup::
