[2024-11-18T15:56:30.885+0000] {local_task_job_runner.py:123} INFO - ::group::Pre task execution logs
[2024-11-18T15:56:30.902+0000] {taskinstance.py:2612} INFO - Dependencies all met for dep_context=non-requeueable deps ti=<TaskInstance: Ciril_group.load_to_db scheduled__2024-11-17T00:00:00+00:00 [queued]>
[2024-11-18T15:56:30.910+0000] {taskinstance.py:2612} INFO - Dependencies all met for dep_context=requeueable deps ti=<TaskInstance: Ciril_group.load_to_db scheduled__2024-11-17T00:00:00+00:00 [queued]>
[2024-11-18T15:56:30.911+0000] {taskinstance.py:2865} INFO - Starting attempt 1 of 6
[2024-11-18T15:56:30.922+0000] {taskinstance.py:2888} INFO - Executing <Task(DockerOperator): load_to_db> on 2024-11-17 00:00:00+00:00
[2024-11-18T15:56:30.929+0000] {standard_task_runner.py:104} INFO - Running: ['***', 'tasks', 'run', 'Ciril_group', 'load_to_db', 'scheduled__2024-11-17T00:00:00+00:00', '--job-id', '8', '--raw', '--subdir', 'DAGS_FOLDER/ciril_group_dag.py', '--cfg-path', '/tmp/tmpxrs_f4yl']
[2024-11-18T15:56:30.931+0000] {standard_task_runner.py:105} INFO - Job 8: Subtask load_to_db
[2024-11-18T15:56:30.932+0000] {logging_mixin.py:190} WARNING - /home/***/.local/lib/python3.12/site-packages/***/task/task_runner/standard_task_runner.py:70 DeprecationWarning: This process (pid=253) is multi-threaded, use of fork() may lead to deadlocks in the child.
[2024-11-18T15:56:30.933+0000] {standard_task_runner.py:72} INFO - Started process 255 to run task
[2024-11-18T15:56:30.968+0000] {task_command.py:467} INFO - Running <TaskInstance: Ciril_group.load_to_db scheduled__2024-11-17T00:00:00+00:00 [running]> on host a2bc12b8c1cb
[2024-11-18T15:56:31.033+0000] {taskinstance.py:3131} INFO - Exporting env vars: AIRFLOW_CTX_DAG_OWNER='Simo' AIRFLOW_CTX_DAG_ID='Ciril_group' AIRFLOW_CTX_TASK_ID='load_to_db' AIRFLOW_CTX_EXECUTION_DATE='2024-11-17T00:00:00+00:00' AIRFLOW_CTX_TRY_NUMBER='1' AIRFLOW_CTX_DAG_RUN_ID='scheduled__2024-11-17T00:00:00+00:00'
[2024-11-18T15:56:31.033+0000] {taskinstance.py:731} INFO - ::endgroup::
[2024-11-18T15:56:31.074+0000] {docker.py:367} INFO - Starting docker container from image ***_ciril:latest
[2024-11-18T15:56:38.958+0000] {docker.py:438} INFO - 
[2024-11-18T15:56:39.599+0000] {docker.py:438} INFO - /opt/***/load-csv/load_to_db.py:13: RemovedIn20Warning: [31mDeprecated API features detected! These feature(s) are not compatible with SQLAlchemy 2.0. [32mTo prevent incompatible upgrades prior to updating applications, ensure requirements files are pinned to "sqlalchemy<2.0". [36mSet environment variable SQLALCHEMY_WARN_20=1 to show all deprecation warnings.  Set environment variable SQLALCHEMY_SILENCE_UBER_WARNING=1 to silence this message.[0m (Background on SQLAlchemy 2.0 at: https://sqlalche.me/e/b8d9)
[2024-11-18T15:56:39.600+0000] {docker.py:438} INFO -   metadata = sqlalchemy.schema.MetaData(engine)
[2024-11-18T15:56:39.601+0000] {docker.py:438} INFO - Connexion Ã  la base de donnÃ©es rÃ©ussie
[2024-11-18T15:56:39.611+0000] {docker.py:438} INFO - Traceback (most recent call last):
[2024-11-18T15:56:39.612+0000] {docker.py:438} INFO -   File "/home/***/.local/lib/python3.12/site-packages/sqlalchemy/engine/base.py", line 1910, in _execute_context
[2024-11-18T15:56:39.612+0000] {docker.py:438} INFO - self.dialect.do_execute(
[2024-11-18T15:56:39.613+0000] {docker.py:438} INFO -   File "/home/***/.local/lib/python3.12/site-packages/sqlalchemy/engine/default.py", line 736, in do_execute
[2024-11-18T15:56:39.613+0000] {docker.py:438} INFO -     cursor.execute(statement, parameters)
[2024-11-18T15:56:39.614+0000] {docker.py:438} INFO -   File "/home/***/.local/lib/python3.12/site-packages/MySQLdb/cursors.py", line 206, in execute
[2024-11-18T15:56:39.614+0000] {docker.py:438} INFO -     res = self._query(query)
[2024-11-18T15:56:39.614+0000] {docker.py:438} INFO -           ^^^^^^^^^^^^^^^^^^
[2024-11-18T15:56:39.615+0000] {docker.py:438} INFO -   File "/home/***/.local/lib/python3.12/site-packages/MySQLdb/cursors.py", line 319, in _query
[2024-11-18T15:56:39.615+0000] {docker.py:438} INFO -     db.query(q)
[2024-11-18T15:56:39.616+0000] {docker.py:438} INFO -   File "/home/***/.local/lib/python3.12/site-packages/MySQLdb/connections.py", line 254, in query
[2024-11-18T15:56:39.616+0000] {docker.py:438} INFO -     _mysql.connection.query(self, query)
[2024-11-18T15:56:39.617+0000] {docker.py:438} INFO - MySQLdb.ProgrammingError: (1146, "Table 'db_dteng.places' doesn't exist")
[2024-11-18T15:56:39.617+0000] {docker.py:438} INFO - 
[2024-11-18T15:56:39.618+0000] {docker.py:438} INFO - The above exception was the direct cause of the following exception:
[2024-11-18T15:56:39.619+0000] {docker.py:438} INFO - 
[2024-11-18T15:56:39.619+0000] {docker.py:438} INFO - Traceback (most recent call last):
[2024-11-18T15:56:39.620+0000] {docker.py:438} INFO -   File "/home/***/.local/lib/python3.12/site-packages/sqlalchemy/dialects/mysql/base.py", line 3220, in _show_create_table
[2024-11-18T15:56:39.620+0000] {docker.py:438} INFO - ).exec_driver_sql(st)
[2024-11-18T15:56:39.621+0000] {docker.py:438} INFO -       ^^^^^^^^^^^^^^^^^^^
[2024-11-18T15:56:39.621+0000] {docker.py:438} INFO -   File "/home/***/.local/lib/python3.12/site-packages/sqlalchemy/engine/base.py", line 1770, in exec_driver_sql
[2024-11-18T15:56:39.622+0000] {docker.py:438} INFO -     return self._exec_driver_sql(
[2024-11-18T15:56:39.622+0000] {docker.py:438} INFO -            ^^^^^^^^^^^^^^^^^^^^^^
[2024-11-18T15:56:39.623+0000] {docker.py:438} INFO -   File "/home/***/.local/lib/python3.12/site-packages/sqlalchemy/engine/base.py", line 1674, in _exec_driver_sql
[2024-11-18T15:56:39.623+0000] {docker.py:438} INFO -     ret = self._execute_context(
[2024-11-18T15:56:39.623+0000] {docker.py:438} INFO -           ^^^^^^^^^^^^^^^^^^^^^^
[2024-11-18T15:56:39.624+0000] {docker.py:438} INFO -   File "/home/***/.local/lib/python3.12/site-packages/sqlalchemy/engine/base.py", line 1953, in _execute_context
[2024-11-18T15:56:39.624+0000] {docker.py:438} INFO -     self._handle_dbapi_exception(
[2024-11-18T15:56:39.624+0000] {docker.py:438} INFO -   File "/home/***/.local/lib/python3.12/site-packages/sqlalchemy/engine/base.py", line 2134, in _handle_dbapi_exception
[2024-11-18T15:56:39.625+0000] {docker.py:438} INFO -     util.raise_(
[2024-11-18T15:56:39.625+0000] {docker.py:438} INFO -   File "/home/***/.local/lib/python3.12/site-packages/sqlalchemy/util/compat.py", line 211, in raise_
[2024-11-18T15:56:39.626+0000] {docker.py:438} INFO -     raise exception
[2024-11-18T15:56:39.626+0000] {docker.py:438} INFO -   File "/home/***/.local/lib/python3.12/site-packages/sqlalchemy/engine/base.py", line 1910, in _execute_context
[2024-11-18T15:56:39.626+0000] {docker.py:438} INFO -     self.dialect.do_execute(
[2024-11-18T15:56:39.627+0000] {docker.py:438} INFO -   File "/home/***/.local/lib/python3.12/site-packages/sqlalchemy/engine/default.py", line 736, in do_execute
[2024-11-18T15:56:39.627+0000] {docker.py:438} INFO -     cursor.execute(statement, parameters)
[2024-11-18T15:56:39.627+0000] {docker.py:438} INFO -   File "/home/***/.local/lib/python3.12/site-packages/MySQLdb/cursors.py", line 206, in execute
[2024-11-18T15:56:39.628+0000] {docker.py:438} INFO -     res = self._query(query)
[2024-11-18T15:56:39.628+0000] {docker.py:438} INFO -           ^^^^^^^^^^^^^^^^^^
[2024-11-18T15:56:39.628+0000] {docker.py:438} INFO -   File "/home/***/.local/lib/python3.12/site-packages/MySQLdb/cursors.py", line 319, in _query
[2024-11-18T15:56:39.629+0000] {docker.py:438} INFO -     db.query(q)
[2024-11-18T15:56:39.629+0000] {docker.py:438} INFO -   File "/home/***/.local/lib/python3.12/site-packages/MySQLdb/connections.py", line 254, in query
[2024-11-18T15:56:39.629+0000] {docker.py:438} INFO -     _mysql.connection.query(self, query)
[2024-11-18T15:56:39.629+0000] {docker.py:438} INFO - sqlalchemy.exc.ProgrammingError: (MySQLdb.ProgrammingError) (1146, "Table 'db_dteng.places' doesn't exist")
[2024-11-18T15:56:39.630+0000] {docker.py:438} INFO - [SQL: SHOW CREATE TABLE `places`]
[2024-11-18T15:56:39.630+0000] {docker.py:438} INFO - (Background on this error at: https://sqlalche.me/e/14/f405)
[2024-11-18T15:56:39.631+0000] {docker.py:438} INFO - 
[2024-11-18T15:56:39.631+0000] {docker.py:438} INFO - The above exception was the direct cause of the following exception:
[2024-11-18T15:56:39.631+0000] {docker.py:438} INFO - 
[2024-11-18T15:56:39.632+0000] {docker.py:438} INFO - Traceback (most recent call last):
[2024-11-18T15:56:39.632+0000] {docker.py:438} INFO -   File "/opt/***/load-csv/load_to_db.py", line 23, in <module>
[2024-11-18T15:56:39.633+0000] {docker.py:438} INFO -     Places=   sqlalchemy.schema.Table('places', metadata, autoload=True, autoload_with=engine)
[2024-11-18T15:56:39.633+0000] {docker.py:438} INFO -               ^^^^^^^^^^^^^^^^^^^^^^^^^^^^^^^^^^^^^^^^^^^^^^^^^^^^^^^^^^^^^^^^^^^^^^^^^^^^^^^^
[2024-11-18T15:56:39.633+0000] {docker.py:438} INFO -   File "<string>", line 2, in __new__
[2024-11-18T15:56:39.634+0000] {docker.py:438} INFO -   File "/home/***/.local/lib/python3.12/site-packages/sqlalchemy/util/deprecations.py", line 375, in warned
[2024-11-18T15:56:39.634+0000] {docker.py:438} INFO -     return fn(*args, **kwargs)
[2024-11-18T15:56:39.634+0000] {docker.py:438} INFO -            ^^^^^^^^^^^^^^^^^^^
[2024-11-18T15:56:39.635+0000] {docker.py:438} INFO -   File "/home/***/.local/lib/python3.12/site-packages/sqlalchemy/sql/schema.py", line 618, in __new__
[2024-11-18T15:56:39.635+0000] {docker.py:438} INFO -     with util.safe_reraise():
[2024-11-18T15:56:39.636+0000] {docker.py:438} INFO -          ^^^^^^^^^^^^^^^^^^^
[2024-11-18T15:56:39.636+0000] {docker.py:438} INFO -   File "/home/***/.local/lib/python3.12/site-packages/sqlalchemy/util/langhelpers.py", line 70, in __exit__
[2024-11-18T15:56:39.637+0000] {docker.py:438} INFO -     compat.raise_(
[2024-11-18T15:56:39.637+0000] {docker.py:438} INFO -   File "/home/***/.local/lib/python3.12/site-packages/sqlalchemy/util/compat.py", line 211, in raise_
[2024-11-18T15:56:39.638+0000] {docker.py:438} INFO -     raise exception
[2024-11-18T15:56:39.638+0000] {docker.py:438} INFO -   File "/home/***/.local/lib/python3.12/site-packages/sqlalchemy/sql/schema.py", line 614, in __new__
[2024-11-18T15:56:39.638+0000] {docker.py:438} INFO -     table._init(name, metadata, *args, **kw)
[2024-11-18T15:56:39.639+0000] {docker.py:438} INFO -   File "/home/***/.local/lib/python3.12/site-packages/sqlalchemy/sql/schema.py", line 689, in _init
[2024-11-18T15:56:39.639+0000] {docker.py:438} INFO -     self._autoload(
[2024-11-18T15:56:39.639+0000] {docker.py:438} INFO -   File "/home/***/.local/lib/python3.12/site-packages/sqlalchemy/sql/schema.py", line 724, in _autoload
[2024-11-18T15:56:39.640+0000] {docker.py:438} INFO -     conn_insp.reflect_table(
[2024-11-18T15:56:39.640+0000] {docker.py:438} INFO -   File "/home/***/.local/lib/python3.12/site-packages/sqlalchemy/engine/reflection.py", line 757, in reflect_table
[2024-11-18T15:56:39.640+0000] {docker.py:438} INFO - tbl_opts = self.get_table_options(
[2024-11-18T15:56:39.641+0000] {docker.py:438} INFO -                ^^^^^^^^^^^^^^^^^^^^^^^
[2024-11-18T15:56:39.641+0000] {docker.py:438} INFO -   File "/home/***/.local/lib/python3.12/site-packages/sqlalchemy/engine/reflection.py", line 398, in get_table_options
[2024-11-18T15:56:39.641+0000] {docker.py:438} INFO -     return self.dialect.get_table_options(
[2024-11-18T15:56:39.642+0000] {docker.py:438} INFO -            ^^^^^^^^^^^^^^^^^^^^^^^^^^^^^^^
[2024-11-18T15:56:39.642+0000] {docker.py:438} INFO -   File "<string>", line 2, in get_table_options
[2024-11-18T15:56:39.642+0000] {docker.py:438} INFO -   File "/home/***/.local/lib/python3.12/site-packages/sqlalchemy/engine/reflection.py", line 55, in cache
[2024-11-18T15:56:39.643+0000] {docker.py:438} INFO -     ret = fn(self, con, *args, **kw)
[2024-11-18T15:56:39.643+0000] {docker.py:438} INFO -           ^^^^^^^^^^^^^^^^^^^^^^^^^^
[2024-11-18T15:56:39.643+0000] {docker.py:438} INFO -   File "/home/***/.local/lib/python3.12/site-packages/sqlalchemy/dialects/mysql/base.py", line 2828, in get_table_options
[2024-11-18T15:56:39.644+0000] {docker.py:438} INFO -     parsed_state = self._parsed_state_or_create(
[2024-11-18T15:56:39.644+0000] {docker.py:438} INFO -                    ^^^^^^^^^^^^^^^^^^^^^^^^^^^^^
[2024-11-18T15:56:39.644+0000] {docker.py:438} INFO -   File "/home/***/.local/lib/python3.12/site-packages/sqlalchemy/dialects/mysql/base.py", line 3085, in _parsed_state_or_create
[2024-11-18T15:56:39.645+0000] {docker.py:438} INFO -     return self._setup_parser(
[2024-11-18T15:56:39.645+0000] {docker.py:438} INFO -            ^^^^^^^^^^^^^^^^^^^
[2024-11-18T15:56:39.645+0000] {docker.py:438} INFO -   File "<string>", line 2, in _setup_parser
[2024-11-18T15:56:39.645+0000] {docker.py:438} INFO -   File "/home/***/.local/lib/python3.12/site-packages/sqlalchemy/engine/reflection.py", line 55, in cache
[2024-11-18T15:56:39.646+0000] {docker.py:438} INFO -     ret = fn(self, con, *args, **kw)
[2024-11-18T15:56:39.646+0000] {docker.py:438} INFO -           ^^^^^^^^^^^^^^^^^^^^^^^^^^
[2024-11-18T15:56:39.646+0000] {docker.py:438} INFO -   File "/home/***/.local/lib/python3.12/site-packages/sqlalchemy/dialects/mysql/base.py", line 3112, in _setup_parser
[2024-11-18T15:56:39.647+0000] {docker.py:438} INFO -     sql = self._show_create_table(
[2024-11-18T15:56:39.647+0000] {docker.py:438} INFO -           ^^^^^^^^^^^^^^^^^^^^^^^^
[2024-11-18T15:56:39.648+0000] {docker.py:438} INFO -   File "/home/***/.local/lib/python3.12/site-packages/sqlalchemy/dialects/mysql/base.py", line 3223, in _show_create_table
[2024-11-18T15:56:39.648+0000] {docker.py:438} INFO -     util.raise_(exc.NoSuchTableError(full_name), replace_context=e)
[2024-11-18T15:56:39.648+0000] {docker.py:438} INFO -   File "/home/***/.local/lib/python3.12/site-packages/sqlalchemy/util/compat.py", line 211, in raise_
[2024-11-18T15:56:39.649+0000] {docker.py:438} INFO -     raise exception
[2024-11-18T15:56:39.649+0000] {docker.py:438} INFO - sqlalchemy.exc.NoSuchTableError: `places`
[2024-11-18T15:56:40.242+0000] {taskinstance.py:3310} ERROR - Task failed with exception
Traceback (most recent call last):
  File "/home/airflow/.local/lib/python3.12/site-packages/airflow/models/taskinstance.py", line 767, in _execute_task
    result = _execute_callable(context=context, **execute_callable_kwargs)
             ^^^^^^^^^^^^^^^^^^^^^^^^^^^^^^^^^^^^^^^^^^^^^^^^^^^^^^^^^^^^^
  File "/home/airflow/.local/lib/python3.12/site-packages/airflow/models/taskinstance.py", line 733, in _execute_callable
    return ExecutionCallableRunner(
           ^^^^^^^^^^^^^^^^^^^^^^^^
  File "/home/airflow/.local/lib/python3.12/site-packages/airflow/utils/operator_helpers.py", line 252, in run
    return self.func(*args, **kwargs)
           ^^^^^^^^^^^^^^^^^^^^^^^^^^
  File "/home/airflow/.local/lib/python3.12/site-packages/airflow/models/baseoperator.py", line 406, in wrapper
    return func(self, *args, **kwargs)
           ^^^^^^^^^^^^^^^^^^^^^^^^^^^
  File "/home/airflow/.local/lib/python3.12/site-packages/airflow/providers/docker/operators/docker.py", line 513, in execute
    return self._run_image()
           ^^^^^^^^^^^^^^^^^
  File "/home/airflow/.local/lib/python3.12/site-packages/airflow/providers/docker/operators/docker.py", line 372, in _run_image
    return self._run_image_with_mounts([*self.mounts, tmp_mount], add_tmp_variable=True)
           ^^^^^^^^^^^^^^^^^^^^^^^^^^^^^^^^^^^^^^^^^^^^^^^^^^^^^^^^^^^^^^^^^^^^^^^^^^^^^
  File "/home/airflow/.local/lib/python3.12/site-packages/airflow/providers/docker/operators/docker.py", line 446, in _run_image_with_mounts
    raise DockerContainerFailedException(f"Docker container failed: {result!r}", logs=log_lines)
airflow.providers.docker.exceptions.DockerContainerFailedException: Docker container failed: {'StatusCode': 1}
[2024-11-18T15:56:40.249+0000] {taskinstance.py:1225} INFO - Marking task as UP_FOR_RETRY. dag_id=Ciril_group, task_id=load_to_db, run_id=scheduled__2024-11-17T00:00:00+00:00, execution_date=20241117T000000, start_date=20241118T155630, end_date=20241118T155640
[2024-11-18T15:56:40.263+0000] {taskinstance.py:340} INFO - ::group::Post task execution logs
[2024-11-18T15:56:40.265+0000] {standard_task_runner.py:124} ERROR - Failed to execute job 8 for task load_to_db (Docker container failed: {'StatusCode': 1}; 255)
Traceback (most recent call last):
  File "/home/airflow/.local/lib/python3.12/site-packages/airflow/task/task_runner/standard_task_runner.py", line 117, in _start_by_fork
    ret = args.func(args, dag=self.dag)
          ^^^^^^^^^^^^^^^^^^^^^^^^^^^^^
  File "/home/airflow/.local/lib/python3.12/site-packages/airflow/cli/cli_config.py", line 49, in command
    return func(*args, **kwargs)
           ^^^^^^^^^^^^^^^^^^^^^
  File "/home/airflow/.local/lib/python3.12/site-packages/airflow/utils/cli.py", line 115, in wrapper
    return f(*args, **kwargs)
           ^^^^^^^^^^^^^^^^^^
  File "/home/airflow/.local/lib/python3.12/site-packages/airflow/cli/commands/task_command.py", line 483, in task_run
    task_return_code = _run_task_by_selected_method(args, _dag, ti)
                       ^^^^^^^^^^^^^^^^^^^^^^^^^^^^^^^^^^^^^^^^^^^^
  File "/home/airflow/.local/lib/python3.12/site-packages/airflow/cli/commands/task_command.py", line 256, in _run_task_by_selected_method
    return _run_raw_task(args, ti)
           ^^^^^^^^^^^^^^^^^^^^^^^
  File "/home/airflow/.local/lib/python3.12/site-packages/airflow/cli/commands/task_command.py", line 341, in _run_raw_task
    return ti._run_raw_task(
           ^^^^^^^^^^^^^^^^^
  File "/home/airflow/.local/lib/python3.12/site-packages/airflow/utils/session.py", line 97, in wrapper
    return func(*args, session=session, **kwargs)
           ^^^^^^^^^^^^^^^^^^^^^^^^^^^^^^^^^^^^^^
  File "/home/airflow/.local/lib/python3.12/site-packages/airflow/models/taskinstance.py", line 3004, in _run_raw_task
    return _run_raw_task(
           ^^^^^^^^^^^^^^
  File "/home/airflow/.local/lib/python3.12/site-packages/airflow/models/taskinstance.py", line 273, in _run_raw_task
    TaskInstance._execute_task_with_callbacks(
  File "/home/airflow/.local/lib/python3.12/site-packages/airflow/models/taskinstance.py", line 3158, in _execute_task_with_callbacks
    result = self._execute_task(context, task_orig)
             ^^^^^^^^^^^^^^^^^^^^^^^^^^^^^^^^^^^^^^
  File "/home/airflow/.local/lib/python3.12/site-packages/airflow/models/taskinstance.py", line 3182, in _execute_task
    return _execute_task(self, context, task_orig)
           ^^^^^^^^^^^^^^^^^^^^^^^^^^^^^^^^^^^^^^^
  File "/home/airflow/.local/lib/python3.12/site-packages/airflow/models/taskinstance.py", line 767, in _execute_task
    result = _execute_callable(context=context, **execute_callable_kwargs)
             ^^^^^^^^^^^^^^^^^^^^^^^^^^^^^^^^^^^^^^^^^^^^^^^^^^^^^^^^^^^^^
  File "/home/airflow/.local/lib/python3.12/site-packages/airflow/models/taskinstance.py", line 733, in _execute_callable
    return ExecutionCallableRunner(
           ^^^^^^^^^^^^^^^^^^^^^^^^
  File "/home/airflow/.local/lib/python3.12/site-packages/airflow/utils/operator_helpers.py", line 252, in run
    return self.func(*args, **kwargs)
           ^^^^^^^^^^^^^^^^^^^^^^^^^^
  File "/home/airflow/.local/lib/python3.12/site-packages/airflow/models/baseoperator.py", line 406, in wrapper
    return func(self, *args, **kwargs)
           ^^^^^^^^^^^^^^^^^^^^^^^^^^^
  File "/home/airflow/.local/lib/python3.12/site-packages/airflow/providers/docker/operators/docker.py", line 513, in execute
    return self._run_image()
           ^^^^^^^^^^^^^^^^^
  File "/home/airflow/.local/lib/python3.12/site-packages/airflow/providers/docker/operators/docker.py", line 372, in _run_image
    return self._run_image_with_mounts([*self.mounts, tmp_mount], add_tmp_variable=True)
           ^^^^^^^^^^^^^^^^^^^^^^^^^^^^^^^^^^^^^^^^^^^^^^^^^^^^^^^^^^^^^^^^^^^^^^^^^^^^^
  File "/home/airflow/.local/lib/python3.12/site-packages/airflow/providers/docker/operators/docker.py", line 446, in _run_image_with_mounts
    raise DockerContainerFailedException(f"Docker container failed: {result!r}", logs=log_lines)
airflow.providers.docker.exceptions.DockerContainerFailedException: Docker container failed: {'StatusCode': 1}
[2024-11-18T15:56:40.292+0000] {local_task_job_runner.py:266} INFO - Task exited with return code 1
[2024-11-18T15:56:40.321+0000] {taskinstance.py:3900} INFO - 0 downstream tasks scheduled from follow-on schedule check
[2024-11-18T15:56:40.323+0000] {local_task_job_runner.py:245} INFO - ::endgroup::
[2024-11-18T16:02:33.468+0000] {local_task_job_runner.py:123} INFO - ::group::Pre task execution logs
[2024-11-18T16:02:33.485+0000] {taskinstance.py:2612} INFO - Dependencies all met for dep_context=non-requeueable deps ti=<TaskInstance: Ciril_group.load_to_db scheduled__2024-11-17T00:00:00+00:00 [queued]>
[2024-11-18T16:02:33.496+0000] {taskinstance.py:2612} INFO - Dependencies all met for dep_context=requeueable deps ti=<TaskInstance: Ciril_group.load_to_db scheduled__2024-11-17T00:00:00+00:00 [queued]>
[2024-11-18T16:02:33.497+0000] {taskinstance.py:2865} INFO - Starting attempt 1 of 6
[2024-11-18T16:02:33.510+0000] {taskinstance.py:2888} INFO - Executing <Task(DockerOperator): load_to_db> on 2024-11-17 00:00:00+00:00
[2024-11-18T16:02:33.518+0000] {standard_task_runner.py:104} INFO - Running: ['***', 'tasks', 'run', 'Ciril_group', 'load_to_db', 'scheduled__2024-11-17T00:00:00+00:00', '--job-id', '7', '--raw', '--subdir', 'DAGS_FOLDER/ciril_group_dag.py', '--cfg-path', '/tmp/tmpo0urh75b']
[2024-11-18T16:02:33.521+0000] {standard_task_runner.py:105} INFO - Job 7: Subtask load_to_db
[2024-11-18T16:02:33.524+0000] {logging_mixin.py:190} WARNING - /home/***/.local/lib/python3.12/site-packages/***/task/task_runner/standard_task_runner.py:70 DeprecationWarning: This process (pid=214) is multi-threaded, use of fork() may lead to deadlocks in the child.
[2024-11-18T16:02:33.525+0000] {standard_task_runner.py:72} INFO - Started process 215 to run task
[2024-11-18T16:02:33.563+0000] {task_command.py:467} INFO - Running <TaskInstance: Ciril_group.load_to_db scheduled__2024-11-17T00:00:00+00:00 [running]> on host 1d5bdcb3fd32
[2024-11-18T16:02:33.636+0000] {taskinstance.py:3131} INFO - Exporting env vars: AIRFLOW_CTX_DAG_OWNER='Simo' AIRFLOW_CTX_DAG_ID='Ciril_group' AIRFLOW_CTX_TASK_ID='load_to_db' AIRFLOW_CTX_EXECUTION_DATE='2024-11-17T00:00:00+00:00' AIRFLOW_CTX_TRY_NUMBER='1' AIRFLOW_CTX_DAG_RUN_ID='scheduled__2024-11-17T00:00:00+00:00'
[2024-11-18T16:02:33.637+0000] {taskinstance.py:731} INFO - ::endgroup::
[2024-11-18T16:02:33.685+0000] {docker.py:367} INFO - Starting docker container from image ***_ciril:latest
[2024-11-18T16:02:41.249+0000] {docker.py:438} INFO - 
[2024-11-18T16:02:41.836+0000] {docker.py:438} INFO - /opt/***/load-csv/load_to_db.py:13: RemovedIn20Warning: [31mDeprecated API features detected! These feature(s) are not compatible with SQLAlchemy 2.0. [32mTo prevent incompatible upgrades prior to updating applications, ensure requirements files are pinned to "sqlalchemy<2.0". [36mSet environment variable SQLALCHEMY_WARN_20=1 to show all deprecation warnings.  Set environment variable SQLALCHEMY_SILENCE_UBER_WARNING=1 to silence this message.[0m (Background on SQLAlchemy 2.0 at: https://sqlalche.me/e/b8d9)
[2024-11-18T16:02:41.839+0000] {docker.py:438} INFO -   metadata = sqlalchemy.schema.MetaData(engine)
[2024-11-18T16:02:41.840+0000] {docker.py:438} INFO - Connexion Ã  la base de donnÃ©es rÃ©ussie
[2024-11-18T16:02:41.851+0000] {docker.py:438} INFO - Traceback (most recent call last):
[2024-11-18T16:02:41.852+0000] {docker.py:438} INFO -   File "/home/***/.local/lib/python3.12/site-packages/sqlalchemy/engine/base.py", line 1910, in _execute_context
[2024-11-18T16:02:41.852+0000] {docker.py:438} INFO - self.dialect.do_execute(
[2024-11-18T16:02:41.853+0000] {docker.py:438} INFO -   File "/home/***/.local/lib/python3.12/site-packages/sqlalchemy/engine/default.py", line 736, in do_execute
[2024-11-18T16:02:41.854+0000] {docker.py:438} INFO -     cursor.execute(statement, parameters)
[2024-11-18T16:02:41.854+0000] {docker.py:438} INFO -   File "/home/***/.local/lib/python3.12/site-packages/MySQLdb/cursors.py", line 206, in execute
[2024-11-18T16:02:41.855+0000] {docker.py:438} INFO -     res = self._query(query)
[2024-11-18T16:02:41.855+0000] {docker.py:438} INFO -           ^^^^^^^^^^^^^^^^^^
[2024-11-18T16:02:41.856+0000] {docker.py:438} INFO -   File "/home/***/.local/lib/python3.12/site-packages/MySQLdb/cursors.py", line 319, in _query
[2024-11-18T16:02:41.857+0000] {docker.py:438} INFO -     db.query(q)
[2024-11-18T16:02:41.857+0000] {docker.py:438} INFO -   File "/home/***/.local/lib/python3.12/site-packages/MySQLdb/connections.py", line 254, in query
[2024-11-18T16:02:41.858+0000] {docker.py:438} INFO -     _mysql.connection.query(self, query)
[2024-11-18T16:02:41.859+0000] {docker.py:438} INFO - MySQLdb.ProgrammingError: (1146, "Table 'db_dteng.places' doesn't exist")
[2024-11-18T16:02:41.859+0000] {docker.py:438} INFO - 
[2024-11-18T16:02:41.860+0000] {docker.py:438} INFO - The above exception was the direct cause of the following exception:
[2024-11-18T16:02:41.860+0000] {docker.py:438} INFO - 
[2024-11-18T16:02:41.861+0000] {docker.py:438} INFO - Traceback (most recent call last):
[2024-11-18T16:02:41.861+0000] {docker.py:438} INFO -   File "/home/***/.local/lib/python3.12/site-packages/sqlalchemy/dialects/mysql/base.py", line 3220, in _show_create_table
[2024-11-18T16:02:41.862+0000] {docker.py:438} INFO - ).exec_driver_sql(st)
[2024-11-18T16:02:41.862+0000] {docker.py:438} INFO -       ^^^^^^^^^^^^^^^^^^^
[2024-11-18T16:02:41.862+0000] {docker.py:438} INFO -   File "/home/***/.local/lib/python3.12/site-packages/sqlalchemy/engine/base.py", line 1770, in exec_driver_sql
[2024-11-18T16:02:41.863+0000] {docker.py:438} INFO -     return self._exec_driver_sql(
[2024-11-18T16:02:41.863+0000] {docker.py:438} INFO -            ^^^^^^^^^^^^^^^^^^^^^^
[2024-11-18T16:02:41.864+0000] {docker.py:438} INFO -   File "/home/***/.local/lib/python3.12/site-packages/sqlalchemy/engine/base.py", line 1674, in _exec_driver_sql
[2024-11-18T16:02:41.864+0000] {docker.py:438} INFO -     ret = self._execute_context(
[2024-11-18T16:02:41.864+0000] {docker.py:438} INFO -           ^^^^^^^^^^^^^^^^^^^^^^
[2024-11-18T16:02:41.865+0000] {docker.py:438} INFO -   File "/home/***/.local/lib/python3.12/site-packages/sqlalchemy/engine/base.py", line 1953, in _execute_context
[2024-11-18T16:02:41.865+0000] {docker.py:438} INFO -     self._handle_dbapi_exception(
[2024-11-18T16:02:41.866+0000] {docker.py:438} INFO -   File "/home/***/.local/lib/python3.12/site-packages/sqlalchemy/engine/base.py", line 2134, in _handle_dbapi_exception
[2024-11-18T16:02:41.866+0000] {docker.py:438} INFO -     util.raise_(
[2024-11-18T16:02:41.866+0000] {docker.py:438} INFO -   File "/home/***/.local/lib/python3.12/site-packages/sqlalchemy/util/compat.py", line 211, in raise_
[2024-11-18T16:02:41.867+0000] {docker.py:438} INFO -     raise exception
[2024-11-18T16:02:41.867+0000] {docker.py:438} INFO -   File "/home/***/.local/lib/python3.12/site-packages/sqlalchemy/engine/base.py", line 1910, in _execute_context
[2024-11-18T16:02:41.867+0000] {docker.py:438} INFO -     self.dialect.do_execute(
[2024-11-18T16:02:41.868+0000] {docker.py:438} INFO -   File "/home/***/.local/lib/python3.12/site-packages/sqlalchemy/engine/default.py", line 736, in do_execute
[2024-11-18T16:02:41.868+0000] {docker.py:438} INFO -     cursor.execute(statement, parameters)
[2024-11-18T16:02:41.869+0000] {docker.py:438} INFO -   File "/home/***/.local/lib/python3.12/site-packages/MySQLdb/cursors.py", line 206, in execute
[2024-11-18T16:02:41.869+0000] {docker.py:438} INFO -     res = self._query(query)
[2024-11-18T16:02:41.869+0000] {docker.py:438} INFO -           ^^^^^^^^^^^^^^^^^^
[2024-11-18T16:02:41.870+0000] {docker.py:438} INFO -   File "/home/***/.local/lib/python3.12/site-packages/MySQLdb/cursors.py", line 319, in _query
[2024-11-18T16:02:41.870+0000] {docker.py:438} INFO -     db.query(q)
[2024-11-18T16:02:41.870+0000] {docker.py:438} INFO -   File "/home/***/.local/lib/python3.12/site-packages/MySQLdb/connections.py", line 254, in query
[2024-11-18T16:02:41.871+0000] {docker.py:438} INFO -     _mysql.connection.query(self, query)
[2024-11-18T16:02:41.871+0000] {docker.py:438} INFO - sqlalchemy.exc.ProgrammingError: (MySQLdb.ProgrammingError) (1146, "Table 'db_dteng.places' doesn't exist")
[2024-11-18T16:02:41.872+0000] {docker.py:438} INFO - [SQL: SHOW CREATE TABLE `places`]
[2024-11-18T16:02:41.872+0000] {docker.py:438} INFO - (Background on this error at: https://sqlalche.me/e/14/f405)
[2024-11-18T16:02:41.873+0000] {docker.py:438} INFO - 
[2024-11-18T16:02:41.873+0000] {docker.py:438} INFO - The above exception was the direct cause of the following exception:
[2024-11-18T16:02:41.873+0000] {docker.py:438} INFO - 
[2024-11-18T16:02:41.874+0000] {docker.py:438} INFO - Traceback (most recent call last):
[2024-11-18T16:02:41.874+0000] {docker.py:438} INFO -   File "/opt/***/load-csv/load_to_db.py", line 23, in <module>
[2024-11-18T16:02:41.874+0000] {docker.py:438} INFO -     Places=   sqlalchemy.schema.Table('places', metadata, autoload=True, autoload_with=engine)
[2024-11-18T16:02:41.875+0000] {docker.py:438} INFO -               ^^^^^^^^^^^^^^^^^^^^^^^^^^^^^^^^^^^^^^^^^^^^^^^^^^^^^^^^^^^^^^^^^^^^^^^^^^^^^^^^
[2024-11-18T16:02:41.875+0000] {docker.py:438} INFO -   File "<string>", line 2, in __new__
[2024-11-18T16:02:41.875+0000] {docker.py:438} INFO -   File "/home/***/.local/lib/python3.12/site-packages/sqlalchemy/util/deprecations.py", line 375, in warned
[2024-11-18T16:02:41.876+0000] {docker.py:438} INFO -     return fn(*args, **kwargs)
[2024-11-18T16:02:41.876+0000] {docker.py:438} INFO -            ^^^^^^^^^^^^^^^^^^^
[2024-11-18T16:02:41.876+0000] {docker.py:438} INFO -   File "/home/***/.local/lib/python3.12/site-packages/sqlalchemy/sql/schema.py", line 618, in __new__
[2024-11-18T16:02:41.877+0000] {docker.py:438} INFO -     with util.safe_reraise():
[2024-11-18T16:02:41.877+0000] {docker.py:438} INFO -          ^^^^^^^^^^^^^^^^^^^
[2024-11-18T16:02:41.877+0000] {docker.py:438} INFO -   File "/home/***/.local/lib/python3.12/site-packages/sqlalchemy/util/langhelpers.py", line 70, in __exit__
[2024-11-18T16:02:41.878+0000] {docker.py:438} INFO -     compat.raise_(
[2024-11-18T16:02:41.878+0000] {docker.py:438} INFO -   File "/home/***/.local/lib/python3.12/site-packages/sqlalchemy/util/compat.py", line 211, in raise_
[2024-11-18T16:02:41.878+0000] {docker.py:438} INFO -     raise exception
[2024-11-18T16:02:41.879+0000] {docker.py:438} INFO -   File "/home/***/.local/lib/python3.12/site-packages/sqlalchemy/sql/schema.py", line 614, in __new__
[2024-11-18T16:02:41.879+0000] {docker.py:438} INFO -     table._init(name, metadata, *args, **kw)
[2024-11-18T16:02:41.879+0000] {docker.py:438} INFO -   File "/home/***/.local/lib/python3.12/site-packages/sqlalchemy/sql/schema.py", line 689, in _init
[2024-11-18T16:02:41.880+0000] {docker.py:438} INFO -     self._autoload(
[2024-11-18T16:02:41.880+0000] {docker.py:438} INFO -   File "/home/***/.local/lib/python3.12/site-packages/sqlalchemy/sql/schema.py", line 724, in _autoload
[2024-11-18T16:02:41.880+0000] {docker.py:438} INFO -     conn_insp.reflect_table(
[2024-11-18T16:02:41.881+0000] {docker.py:438} INFO -   File "/home/***/.local/lib/python3.12/site-packages/sqlalchemy/engine/reflection.py", line 757, in reflect_table
[2024-11-18T16:02:41.881+0000] {docker.py:438} INFO -     tbl_opts = self.get_table_options(
[2024-11-18T16:02:41.881+0000] {docker.py:438} INFO -                ^^^^^^^^^^^^^^^^^^^^^^^
[2024-11-18T16:02:41.882+0000] {docker.py:438} INFO -   File "/home/***/.local/lib/python3.12/site-packages/sqlalchemy/engine/reflection.py", line 398, in get_table_options
[2024-11-18T16:02:41.882+0000] {docker.py:438} INFO -     return self.dialect.get_table_options(
[2024-11-18T16:02:41.883+0000] {docker.py:438} INFO -            ^^^^^^^^^^^^^^^^^^^^^^^^^^^^^^^
[2024-11-18T16:02:41.883+0000] {docker.py:438} INFO -   File "<string>", line 2, in get_table_options
[2024-11-18T16:02:41.883+0000] {docker.py:438} INFO -   File "/home/***/.local/lib/python3.12/site-packages/sqlalchemy/engine/reflection.py", line 55, in cache
[2024-11-18T16:02:41.884+0000] {docker.py:438} INFO -     ret = fn(self, con, *args, **kw)
[2024-11-18T16:02:41.884+0000] {docker.py:438} INFO -           ^^^^^^^^^^^^^^^^^^^^^^^^^^
[2024-11-18T16:02:41.884+0000] {docker.py:438} INFO -   File "/home/***/.local/lib/python3.12/site-packages/sqlalchemy/dialects/mysql/base.py", line 2828, in get_table_options
[2024-11-18T16:02:41.885+0000] {docker.py:438} INFO - parsed_state = self._parsed_state_or_create(
[2024-11-18T16:02:41.885+0000] {docker.py:438} INFO -                    ^^^^^^^^^^^^^^^^^^^^^^^^^^^^^
[2024-11-18T16:02:41.886+0000] {docker.py:438} INFO -   File "/home/***/.local/lib/python3.12/site-packages/sqlalchemy/dialects/mysql/base.py", line 3085, in _parsed_state_or_create
[2024-11-18T16:02:41.886+0000] {docker.py:438} INFO -     return self._setup_parser(
[2024-11-18T16:02:41.886+0000] {docker.py:438} INFO -            ^^^^^^^^^^^^^^^^^^^
[2024-11-18T16:02:41.887+0000] {docker.py:438} INFO -   File "<string>", line 2, in _setup_parser
[2024-11-18T16:02:41.887+0000] {docker.py:438} INFO -   File "/home/***/.local/lib/python3.12/site-packages/sqlalchemy/engine/reflection.py", line 55, in cache
[2024-11-18T16:02:41.887+0000] {docker.py:438} INFO -     ret = fn(self, con, *args, **kw)
[2024-11-18T16:02:41.888+0000] {docker.py:438} INFO -           ^^^^^^^^^^^^^^^^^^^^^^^^^^
[2024-11-18T16:02:41.888+0000] {docker.py:438} INFO -   File "/home/***/.local/lib/python3.12/site-packages/sqlalchemy/dialects/mysql/base.py", line 3112, in _setup_parser
[2024-11-18T16:02:41.889+0000] {docker.py:438} INFO -     sql = self._show_create_table(
[2024-11-18T16:02:41.889+0000] {docker.py:438} INFO -           ^^^^^^^^^^^^^^^^^^^^^^^^
[2024-11-18T16:02:41.889+0000] {docker.py:438} INFO -   File "/home/***/.local/lib/python3.12/site-packages/sqlalchemy/dialects/mysql/base.py", line 3223, in _show_create_table
[2024-11-18T16:02:41.890+0000] {docker.py:438} INFO -     util.raise_(exc.NoSuchTableError(full_name), replace_context=e)
[2024-11-18T16:02:41.890+0000] {docker.py:438} INFO -   File "/home/***/.local/lib/python3.12/site-packages/sqlalchemy/util/compat.py", line 211, in raise_
[2024-11-18T16:02:41.891+0000] {docker.py:438} INFO -     raise exception
[2024-11-18T16:02:41.891+0000] {docker.py:438} INFO - sqlalchemy.exc.NoSuchTableError: `places`
[2024-11-18T16:02:42.547+0000] {taskinstance.py:3310} ERROR - Task failed with exception
Traceback (most recent call last):
  File "/home/airflow/.local/lib/python3.12/site-packages/airflow/models/taskinstance.py", line 767, in _execute_task
    result = _execute_callable(context=context, **execute_callable_kwargs)
             ^^^^^^^^^^^^^^^^^^^^^^^^^^^^^^^^^^^^^^^^^^^^^^^^^^^^^^^^^^^^^
  File "/home/airflow/.local/lib/python3.12/site-packages/airflow/models/taskinstance.py", line 733, in _execute_callable
    return ExecutionCallableRunner(
           ^^^^^^^^^^^^^^^^^^^^^^^^
  File "/home/airflow/.local/lib/python3.12/site-packages/airflow/utils/operator_helpers.py", line 252, in run
    return self.func(*args, **kwargs)
           ^^^^^^^^^^^^^^^^^^^^^^^^^^
  File "/home/airflow/.local/lib/python3.12/site-packages/airflow/models/baseoperator.py", line 406, in wrapper
    return func(self, *args, **kwargs)
           ^^^^^^^^^^^^^^^^^^^^^^^^^^^
  File "/home/airflow/.local/lib/python3.12/site-packages/airflow/providers/docker/operators/docker.py", line 513, in execute
    return self._run_image()
           ^^^^^^^^^^^^^^^^^
  File "/home/airflow/.local/lib/python3.12/site-packages/airflow/providers/docker/operators/docker.py", line 372, in _run_image
    return self._run_image_with_mounts([*self.mounts, tmp_mount], add_tmp_variable=True)
           ^^^^^^^^^^^^^^^^^^^^^^^^^^^^^^^^^^^^^^^^^^^^^^^^^^^^^^^^^^^^^^^^^^^^^^^^^^^^^
  File "/home/airflow/.local/lib/python3.12/site-packages/airflow/providers/docker/operators/docker.py", line 446, in _run_image_with_mounts
    raise DockerContainerFailedException(f"Docker container failed: {result!r}", logs=log_lines)
airflow.providers.docker.exceptions.DockerContainerFailedException: Docker container failed: {'StatusCode': 1}
[2024-11-18T16:02:42.555+0000] {taskinstance.py:1225} INFO - Marking task as UP_FOR_RETRY. dag_id=Ciril_group, task_id=load_to_db, run_id=scheduled__2024-11-17T00:00:00+00:00, execution_date=20241117T000000, start_date=20241118T160233, end_date=20241118T160242
[2024-11-18T16:02:42.569+0000] {taskinstance.py:340} INFO - ::group::Post task execution logs
[2024-11-18T16:02:42.570+0000] {standard_task_runner.py:124} ERROR - Failed to execute job 7 for task load_to_db (Docker container failed: {'StatusCode': 1}; 215)
Traceback (most recent call last):
  File "/home/airflow/.local/lib/python3.12/site-packages/airflow/task/task_runner/standard_task_runner.py", line 117, in _start_by_fork
    ret = args.func(args, dag=self.dag)
          ^^^^^^^^^^^^^^^^^^^^^^^^^^^^^
  File "/home/airflow/.local/lib/python3.12/site-packages/airflow/cli/cli_config.py", line 49, in command
    return func(*args, **kwargs)
           ^^^^^^^^^^^^^^^^^^^^^
  File "/home/airflow/.local/lib/python3.12/site-packages/airflow/utils/cli.py", line 115, in wrapper
    return f(*args, **kwargs)
           ^^^^^^^^^^^^^^^^^^
  File "/home/airflow/.local/lib/python3.12/site-packages/airflow/cli/commands/task_command.py", line 483, in task_run
    task_return_code = _run_task_by_selected_method(args, _dag, ti)
                       ^^^^^^^^^^^^^^^^^^^^^^^^^^^^^^^^^^^^^^^^^^^^
  File "/home/airflow/.local/lib/python3.12/site-packages/airflow/cli/commands/task_command.py", line 256, in _run_task_by_selected_method
    return _run_raw_task(args, ti)
           ^^^^^^^^^^^^^^^^^^^^^^^
  File "/home/airflow/.local/lib/python3.12/site-packages/airflow/cli/commands/task_command.py", line 341, in _run_raw_task
    return ti._run_raw_task(
           ^^^^^^^^^^^^^^^^^
  File "/home/airflow/.local/lib/python3.12/site-packages/airflow/utils/session.py", line 97, in wrapper
    return func(*args, session=session, **kwargs)
           ^^^^^^^^^^^^^^^^^^^^^^^^^^^^^^^^^^^^^^
  File "/home/airflow/.local/lib/python3.12/site-packages/airflow/models/taskinstance.py", line 3004, in _run_raw_task
    return _run_raw_task(
           ^^^^^^^^^^^^^^
  File "/home/airflow/.local/lib/python3.12/site-packages/airflow/models/taskinstance.py", line 273, in _run_raw_task
    TaskInstance._execute_task_with_callbacks(
  File "/home/airflow/.local/lib/python3.12/site-packages/airflow/models/taskinstance.py", line 3158, in _execute_task_with_callbacks
    result = self._execute_task(context, task_orig)
             ^^^^^^^^^^^^^^^^^^^^^^^^^^^^^^^^^^^^^^
  File "/home/airflow/.local/lib/python3.12/site-packages/airflow/models/taskinstance.py", line 3182, in _execute_task
    return _execute_task(self, context, task_orig)
           ^^^^^^^^^^^^^^^^^^^^^^^^^^^^^^^^^^^^^^^
  File "/home/airflow/.local/lib/python3.12/site-packages/airflow/models/taskinstance.py", line 767, in _execute_task
    result = _execute_callable(context=context, **execute_callable_kwargs)
             ^^^^^^^^^^^^^^^^^^^^^^^^^^^^^^^^^^^^^^^^^^^^^^^^^^^^^^^^^^^^^
  File "/home/airflow/.local/lib/python3.12/site-packages/airflow/models/taskinstance.py", line 733, in _execute_callable
    return ExecutionCallableRunner(
           ^^^^^^^^^^^^^^^^^^^^^^^^
  File "/home/airflow/.local/lib/python3.12/site-packages/airflow/utils/operator_helpers.py", line 252, in run
    return self.func(*args, **kwargs)
           ^^^^^^^^^^^^^^^^^^^^^^^^^^
  File "/home/airflow/.local/lib/python3.12/site-packages/airflow/models/baseoperator.py", line 406, in wrapper
    return func(self, *args, **kwargs)
           ^^^^^^^^^^^^^^^^^^^^^^^^^^^
  File "/home/airflow/.local/lib/python3.12/site-packages/airflow/providers/docker/operators/docker.py", line 513, in execute
    return self._run_image()
           ^^^^^^^^^^^^^^^^^
  File "/home/airflow/.local/lib/python3.12/site-packages/airflow/providers/docker/operators/docker.py", line 372, in _run_image
    return self._run_image_with_mounts([*self.mounts, tmp_mount], add_tmp_variable=True)
           ^^^^^^^^^^^^^^^^^^^^^^^^^^^^^^^^^^^^^^^^^^^^^^^^^^^^^^^^^^^^^^^^^^^^^^^^^^^^^
  File "/home/airflow/.local/lib/python3.12/site-packages/airflow/providers/docker/operators/docker.py", line 446, in _run_image_with_mounts
    raise DockerContainerFailedException(f"Docker container failed: {result!r}", logs=log_lines)
airflow.providers.docker.exceptions.DockerContainerFailedException: Docker container failed: {'StatusCode': 1}
[2024-11-18T16:02:42.611+0000] {local_task_job_runner.py:266} INFO - Task exited with return code 1
[2024-11-18T16:02:42.631+0000] {taskinstance.py:3900} INFO - 0 downstream tasks scheduled from follow-on schedule check
[2024-11-18T16:02:42.632+0000] {local_task_job_runner.py:245} INFO - ::endgroup::
[2024-11-18T16:08:10.892+0000] {local_task_job_runner.py:123} INFO - ::group::Pre task execution logs
[2024-11-18T16:08:10.910+0000] {taskinstance.py:2612} INFO - Dependencies all met for dep_context=non-requeueable deps ti=<TaskInstance: Ciril_group.load_to_db scheduled__2024-11-17T00:00:00+00:00 [queued]>
[2024-11-18T16:08:10.918+0000] {taskinstance.py:2612} INFO - Dependencies all met for dep_context=requeueable deps ti=<TaskInstance: Ciril_group.load_to_db scheduled__2024-11-17T00:00:00+00:00 [queued]>
[2024-11-18T16:08:10.919+0000] {taskinstance.py:2865} INFO - Starting attempt 1 of 6
[2024-11-18T16:08:10.933+0000] {taskinstance.py:2888} INFO - Executing <Task(DockerOperator): load_to_db> on 2024-11-17 00:00:00+00:00
[2024-11-18T16:08:10.944+0000] {logging_mixin.py:190} WARNING - /home/***/.local/lib/python3.12/site-packages/***/task/task_runner/standard_task_runner.py:70 DeprecationWarning: This process (pid=262) is multi-threaded, use of fork() may lead to deadlocks in the child.
[2024-11-18T16:08:10.945+0000] {standard_task_runner.py:72} INFO - Started process 264 to run task
[2024-11-18T16:08:10.945+0000] {standard_task_runner.py:104} INFO - Running: ['***', 'tasks', 'run', 'Ciril_group', 'load_to_db', 'scheduled__2024-11-17T00:00:00+00:00', '--job-id', '8', '--raw', '--subdir', 'DAGS_FOLDER/ciril_group_dag.py', '--cfg-path', '/tmp/tmp9qk3mcn8']
[2024-11-18T16:08:10.947+0000] {standard_task_runner.py:105} INFO - Job 8: Subtask load_to_db
[2024-11-18T16:08:10.989+0000] {task_command.py:467} INFO - Running <TaskInstance: Ciril_group.load_to_db scheduled__2024-11-17T00:00:00+00:00 [running]> on host 949de22ee74c
[2024-11-18T16:08:11.092+0000] {taskinstance.py:3131} INFO - Exporting env vars: AIRFLOW_CTX_DAG_OWNER='Simo' AIRFLOW_CTX_DAG_ID='Ciril_group' AIRFLOW_CTX_TASK_ID='load_to_db' AIRFLOW_CTX_EXECUTION_DATE='2024-11-17T00:00:00+00:00' AIRFLOW_CTX_TRY_NUMBER='1' AIRFLOW_CTX_DAG_RUN_ID='scheduled__2024-11-17T00:00:00+00:00'
[2024-11-18T16:08:11.093+0000] {taskinstance.py:731} INFO - ::endgroup::
[2024-11-18T16:08:11.148+0000] {docker.py:367} INFO - Starting docker container from image ***_ciril:latest
[2024-11-18T16:08:18.695+0000] {docker.py:438} INFO - 
[2024-11-18T16:08:19.288+0000] {docker.py:438} INFO - /opt/***/load-csv/load_to_db.py:13: RemovedIn20Warning: [31mDeprecated API features detected! These feature(s) are not compatible with SQLAlchemy 2.0. [32mTo prevent incompatible upgrades prior to updating applications, ensure requirements files are pinned to "sqlalchemy<2.0". [36mSet environment variable SQLALCHEMY_WARN_20=1 to show all deprecation warnings.  Set environment variable SQLALCHEMY_SILENCE_UBER_WARNING=1 to silence this message.[0m (Background on SQLAlchemy 2.0 at: https://sqlalche.me/e/b8d9)
[2024-11-18T16:08:19.288+0000] {docker.py:438} INFO -   metadata = sqlalchemy.schema.MetaData(engine)
[2024-11-18T16:08:19.289+0000] {docker.py:438} INFO - Connexion Ã  la base de donnÃ©es rÃ©ussie
[2024-11-18T16:08:19.299+0000] {docker.py:438} INFO - Traceback (most recent call last):
[2024-11-18T16:08:19.300+0000] {docker.py:438} INFO -   File "/home/***/.local/lib/python3.12/site-packages/sqlalchemy/engine/base.py", line 1910, in _execute_context
[2024-11-18T16:08:19.300+0000] {docker.py:438} INFO - self.dialect.do_execute(
[2024-11-18T16:08:19.301+0000] {docker.py:438} INFO -   File "/home/***/.local/lib/python3.12/site-packages/sqlalchemy/engine/default.py", line 736, in do_execute
[2024-11-18T16:08:19.301+0000] {docker.py:438} INFO -     cursor.execute(statement, parameters)
[2024-11-18T16:08:19.302+0000] {docker.py:438} INFO -   File "/home/***/.local/lib/python3.12/site-packages/MySQLdb/cursors.py", line 206, in execute
[2024-11-18T16:08:19.302+0000] {docker.py:438} INFO -     res = self._query(query)
[2024-11-18T16:08:19.303+0000] {docker.py:438} INFO -           ^^^^^^^^^^^^^^^^^^
[2024-11-18T16:08:19.303+0000] {docker.py:438} INFO -   File "/home/***/.local/lib/python3.12/site-packages/MySQLdb/cursors.py", line 319, in _query
[2024-11-18T16:08:19.304+0000] {docker.py:438} INFO -     db.query(q)
[2024-11-18T16:08:19.304+0000] {docker.py:438} INFO -   File "/home/***/.local/lib/python3.12/site-packages/MySQLdb/connections.py", line 254, in query
[2024-11-18T16:08:19.305+0000] {docker.py:438} INFO -     _mysql.connection.query(self, query)
[2024-11-18T16:08:19.305+0000] {docker.py:438} INFO - MySQLdb.ProgrammingError: (1146, "Table 'db_dteng.places' doesn't exist")
[2024-11-18T16:08:19.306+0000] {docker.py:438} INFO - 
[2024-11-18T16:08:19.306+0000] {docker.py:438} INFO - The above exception was the direct cause of the following exception:
[2024-11-18T16:08:19.307+0000] {docker.py:438} INFO - 
[2024-11-18T16:08:19.307+0000] {docker.py:438} INFO - Traceback (most recent call last):
[2024-11-18T16:08:19.308+0000] {docker.py:438} INFO -   File "/home/***/.local/lib/python3.12/site-packages/sqlalchemy/dialects/mysql/base.py", line 3220, in _show_create_table
[2024-11-18T16:08:19.308+0000] {docker.py:438} INFO - ).exec_driver_sql(st)
[2024-11-18T16:08:19.308+0000] {docker.py:438} INFO -       ^^^^^^^^^^^^^^^^^^^
[2024-11-18T16:08:19.309+0000] {docker.py:438} INFO -   File "/home/***/.local/lib/python3.12/site-packages/sqlalchemy/engine/base.py", line 1770, in exec_driver_sql
[2024-11-18T16:08:19.309+0000] {docker.py:438} INFO -     return self._exec_driver_sql(
[2024-11-18T16:08:19.310+0000] {docker.py:438} INFO -            ^^^^^^^^^^^^^^^^^^^^^^
[2024-11-18T16:08:19.310+0000] {docker.py:438} INFO -   File "/home/***/.local/lib/python3.12/site-packages/sqlalchemy/engine/base.py", line 1674, in _exec_driver_sql
[2024-11-18T16:08:19.310+0000] {docker.py:438} INFO -     ret = self._execute_context(
[2024-11-18T16:08:19.311+0000] {docker.py:438} INFO -           ^^^^^^^^^^^^^^^^^^^^^^
[2024-11-18T16:08:19.311+0000] {docker.py:438} INFO -   File "/home/***/.local/lib/python3.12/site-packages/sqlalchemy/engine/base.py", line 1953, in _execute_context
[2024-11-18T16:08:19.311+0000] {docker.py:438} INFO -     self._handle_dbapi_exception(
[2024-11-18T16:08:19.312+0000] {docker.py:438} INFO -   File "/home/***/.local/lib/python3.12/site-packages/sqlalchemy/engine/base.py", line 2134, in _handle_dbapi_exception
[2024-11-18T16:08:19.312+0000] {docker.py:438} INFO -     util.raise_(
[2024-11-18T16:08:19.312+0000] {docker.py:438} INFO -   File "/home/***/.local/lib/python3.12/site-packages/sqlalchemy/util/compat.py", line 211, in raise_
[2024-11-18T16:08:19.313+0000] {docker.py:438} INFO -     raise exception
[2024-11-18T16:08:19.313+0000] {docker.py:438} INFO -   File "/home/***/.local/lib/python3.12/site-packages/sqlalchemy/engine/base.py", line 1910, in _execute_context
[2024-11-18T16:08:19.314+0000] {docker.py:438} INFO -     self.dialect.do_execute(
[2024-11-18T16:08:19.314+0000] {docker.py:438} INFO -   File "/home/***/.local/lib/python3.12/site-packages/sqlalchemy/engine/default.py", line 736, in do_execute
[2024-11-18T16:08:19.314+0000] {docker.py:438} INFO -     cursor.execute(statement, parameters)
[2024-11-18T16:08:19.315+0000] {docker.py:438} INFO -   File "/home/***/.local/lib/python3.12/site-packages/MySQLdb/cursors.py", line 206, in execute
[2024-11-18T16:08:19.315+0000] {docker.py:438} INFO -     res = self._query(query)
[2024-11-18T16:08:19.315+0000] {docker.py:438} INFO -           ^^^^^^^^^^^^^^^^^^
[2024-11-18T16:08:19.316+0000] {docker.py:438} INFO -   File "/home/***/.local/lib/python3.12/site-packages/MySQLdb/cursors.py", line 319, in _query
[2024-11-18T16:08:19.316+0000] {docker.py:438} INFO -     db.query(q)
[2024-11-18T16:08:19.317+0000] {docker.py:438} INFO -   File "/home/***/.local/lib/python3.12/site-packages/MySQLdb/connections.py", line 254, in query
[2024-11-18T16:08:19.317+0000] {docker.py:438} INFO -     _mysql.connection.query(self, query)
[2024-11-18T16:08:19.318+0000] {docker.py:438} INFO - sqlalchemy.exc.ProgrammingError: (MySQLdb.ProgrammingError) (1146, "Table 'db_dteng.places' doesn't exist")
[2024-11-18T16:08:19.318+0000] {docker.py:438} INFO - [SQL: SHOW CREATE TABLE `places`]
[2024-11-18T16:08:19.319+0000] {docker.py:438} INFO - (Background on this error at: https://sqlalche.me/e/14/f405)
[2024-11-18T16:08:19.319+0000] {docker.py:438} INFO - 
[2024-11-18T16:08:19.319+0000] {docker.py:438} INFO - The above exception was the direct cause of the following exception:
[2024-11-18T16:08:19.320+0000] {docker.py:438} INFO - 
[2024-11-18T16:08:19.320+0000] {docker.py:438} INFO - Traceback (most recent call last):
[2024-11-18T16:08:19.321+0000] {docker.py:438} INFO -   File "/opt/***/load-csv/load_to_db.py", line 23, in <module>
[2024-11-18T16:08:19.321+0000] {docker.py:438} INFO -     Places=   sqlalchemy.schema.Table('places', metadata, autoload=True, autoload_with=engine)
[2024-11-18T16:08:19.321+0000] {docker.py:438} INFO -               ^^^^^^^^^^^^^^^^^^^^^^^^^^^^^^^^^^^^^^^^^^^^^^^^^^^^^^^^^^^^^^^^^^^^^^^^^^^^^^^^
[2024-11-18T16:08:19.322+0000] {docker.py:438} INFO -   File "<string>", line 2, in __new__
[2024-11-18T16:08:19.322+0000] {docker.py:438} INFO -   File "/home/***/.local/lib/python3.12/site-packages/sqlalchemy/util/deprecations.py", line 375, in warned
[2024-11-18T16:08:19.322+0000] {docker.py:438} INFO -     return fn(*args, **kwargs)
[2024-11-18T16:08:19.323+0000] {docker.py:438} INFO -            ^^^^^^^^^^^^^^^^^^^
[2024-11-18T16:08:19.323+0000] {docker.py:438} INFO -   File "/home/***/.local/lib/python3.12/site-packages/sqlalchemy/sql/schema.py", line 618, in __new__
[2024-11-18T16:08:19.324+0000] {docker.py:438} INFO -     with util.safe_reraise():
[2024-11-18T16:08:19.324+0000] {docker.py:438} INFO -          ^^^^^^^^^^^^^^^^^^^
[2024-11-18T16:08:19.324+0000] {docker.py:438} INFO -   File "/home/***/.local/lib/python3.12/site-packages/sqlalchemy/util/langhelpers.py", line 70, in __exit__
[2024-11-18T16:08:19.325+0000] {docker.py:438} INFO -     compat.raise_(
[2024-11-18T16:08:19.325+0000] {docker.py:438} INFO -   File "/home/***/.local/lib/python3.12/site-packages/sqlalchemy/util/compat.py", line 211, in raise_
[2024-11-18T16:08:19.326+0000] {docker.py:438} INFO -     raise exception
[2024-11-18T16:08:19.326+0000] {docker.py:438} INFO -   File "/home/***/.local/lib/python3.12/site-packages/sqlalchemy/sql/schema.py", line 614, in __new__
[2024-11-18T16:08:19.326+0000] {docker.py:438} INFO -     table._init(name, metadata, *args, **kw)
[2024-11-18T16:08:19.327+0000] {docker.py:438} INFO -   File "/home/***/.local/lib/python3.12/site-packages/sqlalchemy/sql/schema.py", line 689, in _init
[2024-11-18T16:08:19.327+0000] {docker.py:438} INFO -     self._autoload(
[2024-11-18T16:08:19.327+0000] {docker.py:438} INFO -   File "/home/***/.local/lib/python3.12/site-packages/sqlalchemy/sql/schema.py", line 724, in _autoload
[2024-11-18T16:08:19.328+0000] {docker.py:438} INFO -     conn_insp.reflect_table(
[2024-11-18T16:08:19.328+0000] {docker.py:438} INFO -   File "/home/***/.local/lib/python3.12/site-packages/sqlalchemy/engine/reflection.py", line 757, in reflect_table
[2024-11-18T16:08:19.328+0000] {docker.py:438} INFO -     tbl_opts = self.get_table_options(
[2024-11-18T16:08:19.329+0000] {docker.py:438} INFO -                ^^^^^^^^^^^^^^^^^^^^^^^
[2024-11-18T16:08:19.329+0000] {docker.py:438} INFO -   File "/home/***/.local/lib/python3.12/site-packages/sqlalchemy/engine/reflection.py", line 398, in get_table_options
[2024-11-18T16:08:19.329+0000] {docker.py:438} INFO -     return self.dialect.get_table_options(
[2024-11-18T16:08:19.330+0000] {docker.py:438} INFO -            ^^^^^^^^^^^^^^^^^^^^^^^^^^^^^^^
[2024-11-18T16:08:19.330+0000] {docker.py:438} INFO -   File "<string>", line 2, in get_table_options
[2024-11-18T16:08:19.330+0000] {docker.py:438} INFO -   File "/home/***/.local/lib/python3.12/site-packages/sqlalchemy/engine/reflection.py", line 55, in cache
[2024-11-18T16:08:19.331+0000] {docker.py:438} INFO -     ret = fn(self, con, *args, **kw)
[2024-11-18T16:08:19.331+0000] {docker.py:438} INFO -           ^^^^^^^^^^^^^^^^^^^^^^^^^^
[2024-11-18T16:08:19.331+0000] {docker.py:438} INFO -   File "/home/***/.local/lib/python3.12/site-packages/sqlalchemy/dialects/mysql/base.py", line 2828, in get_table_options
[2024-11-18T16:08:19.332+0000] {docker.py:438} INFO -     parsed_state = self._parsed_state_or_create(
[2024-11-18T16:08:19.332+0000] {docker.py:438} INFO -                    ^^^^^^^^^^^^^^^^^^^^^^^^^^^^^
[2024-11-18T16:08:19.332+0000] {docker.py:438} INFO -   F
[2024-11-18T16:08:19.333+0000] {docker.py:438} INFO - ile "/home/***/.local/lib/python3.12/site-packages/sqlalchemy/dialects/mysql/base.py", line 3085, in _parsed_state_or_create
[2024-11-18T16:08:19.333+0000] {docker.py:438} INFO -     return self._setup_parser(
[2024-11-18T16:08:19.334+0000] {docker.py:438} INFO -            ^^^^^^^^^^^^^^^^^^^
[2024-11-18T16:08:19.334+0000] {docker.py:438} INFO -   File "<string>", line 2, in _setup_parser
[2024-11-18T16:08:19.335+0000] {docker.py:438} INFO -   File "/home/***/.local/lib/python3.12/site-packages/sqlalchemy/engine/reflection.py", line 55, in cache
[2024-11-18T16:08:19.335+0000] {docker.py:438} INFO -     ret = fn(self, con, *args, **kw)
[2024-11-18T16:08:19.336+0000] {docker.py:438} INFO -           ^^^^^^^^^^^^^^^^^^^^^^^^^^
[2024-11-18T16:08:19.336+0000] {docker.py:438} INFO -   File "/home/***/.local/lib/python3.12/site-packages/sqlalchemy/dialects/mysql/base.py", line 3112, in _setup_parser
[2024-11-18T16:08:19.336+0000] {docker.py:438} INFO -     sql = self._show_create_table(
[2024-11-18T16:08:19.337+0000] {docker.py:438} INFO -           ^^^^^^^^^^^^^^^^^^^^^^^^
[2024-11-18T16:08:19.337+0000] {docker.py:438} INFO -   File "/home/***/.local/lib/python3.12/site-packages/sqlalchemy/dialects/mysql/base.py", line 3223, in _show_create_table
[2024-11-18T16:08:19.338+0000] {docker.py:438} INFO -     util.raise_(exc.NoSuchTableError(full_name), replace_context=e)
[2024-11-18T16:08:19.338+0000] {docker.py:438} INFO -   File "/home/***/.local/lib/python3.12/site-packages/sqlalchemy/util/compat.py", line 211, in raise_
[2024-11-18T16:08:19.338+0000] {docker.py:438} INFO -     raise exception
[2024-11-18T16:08:19.339+0000] {docker.py:438} INFO - sqlalchemy.exc.NoSuchTableError: `places`
[2024-11-18T16:08:19.999+0000] {taskinstance.py:3310} ERROR - Task failed with exception
Traceback (most recent call last):
  File "/home/airflow/.local/lib/python3.12/site-packages/airflow/models/taskinstance.py", line 767, in _execute_task
    result = _execute_callable(context=context, **execute_callable_kwargs)
             ^^^^^^^^^^^^^^^^^^^^^^^^^^^^^^^^^^^^^^^^^^^^^^^^^^^^^^^^^^^^^
  File "/home/airflow/.local/lib/python3.12/site-packages/airflow/models/taskinstance.py", line 733, in _execute_callable
    return ExecutionCallableRunner(
           ^^^^^^^^^^^^^^^^^^^^^^^^
  File "/home/airflow/.local/lib/python3.12/site-packages/airflow/utils/operator_helpers.py", line 252, in run
    return self.func(*args, **kwargs)
           ^^^^^^^^^^^^^^^^^^^^^^^^^^
  File "/home/airflow/.local/lib/python3.12/site-packages/airflow/models/baseoperator.py", line 406, in wrapper
    return func(self, *args, **kwargs)
           ^^^^^^^^^^^^^^^^^^^^^^^^^^^
  File "/home/airflow/.local/lib/python3.12/site-packages/airflow/providers/docker/operators/docker.py", line 513, in execute
    return self._run_image()
           ^^^^^^^^^^^^^^^^^
  File "/home/airflow/.local/lib/python3.12/site-packages/airflow/providers/docker/operators/docker.py", line 372, in _run_image
    return self._run_image_with_mounts([*self.mounts, tmp_mount], add_tmp_variable=True)
           ^^^^^^^^^^^^^^^^^^^^^^^^^^^^^^^^^^^^^^^^^^^^^^^^^^^^^^^^^^^^^^^^^^^^^^^^^^^^^
  File "/home/airflow/.local/lib/python3.12/site-packages/airflow/providers/docker/operators/docker.py", line 446, in _run_image_with_mounts
    raise DockerContainerFailedException(f"Docker container failed: {result!r}", logs=log_lines)
airflow.providers.docker.exceptions.DockerContainerFailedException: Docker container failed: {'StatusCode': 1}
[2024-11-18T16:08:20.006+0000] {taskinstance.py:1225} INFO - Marking task as UP_FOR_RETRY. dag_id=Ciril_group, task_id=load_to_db, run_id=scheduled__2024-11-17T00:00:00+00:00, execution_date=20241117T000000, start_date=20241118T160810, end_date=20241118T160820
[2024-11-18T16:08:20.021+0000] {taskinstance.py:340} INFO - ::group::Post task execution logs
[2024-11-18T16:08:20.022+0000] {standard_task_runner.py:124} ERROR - Failed to execute job 8 for task load_to_db (Docker container failed: {'StatusCode': 1}; 264)
Traceback (most recent call last):
  File "/home/airflow/.local/lib/python3.12/site-packages/airflow/task/task_runner/standard_task_runner.py", line 117, in _start_by_fork
    ret = args.func(args, dag=self.dag)
          ^^^^^^^^^^^^^^^^^^^^^^^^^^^^^
  File "/home/airflow/.local/lib/python3.12/site-packages/airflow/cli/cli_config.py", line 49, in command
    return func(*args, **kwargs)
           ^^^^^^^^^^^^^^^^^^^^^
  File "/home/airflow/.local/lib/python3.12/site-packages/airflow/utils/cli.py", line 115, in wrapper
    return f(*args, **kwargs)
           ^^^^^^^^^^^^^^^^^^
  File "/home/airflow/.local/lib/python3.12/site-packages/airflow/cli/commands/task_command.py", line 483, in task_run
    task_return_code = _run_task_by_selected_method(args, _dag, ti)
                       ^^^^^^^^^^^^^^^^^^^^^^^^^^^^^^^^^^^^^^^^^^^^
  File "/home/airflow/.local/lib/python3.12/site-packages/airflow/cli/commands/task_command.py", line 256, in _run_task_by_selected_method
    return _run_raw_task(args, ti)
           ^^^^^^^^^^^^^^^^^^^^^^^
  File "/home/airflow/.local/lib/python3.12/site-packages/airflow/cli/commands/task_command.py", line 341, in _run_raw_task
    return ti._run_raw_task(
           ^^^^^^^^^^^^^^^^^
  File "/home/airflow/.local/lib/python3.12/site-packages/airflow/utils/session.py", line 97, in wrapper
    return func(*args, session=session, **kwargs)
           ^^^^^^^^^^^^^^^^^^^^^^^^^^^^^^^^^^^^^^
  File "/home/airflow/.local/lib/python3.12/site-packages/airflow/models/taskinstance.py", line 3004, in _run_raw_task
    return _run_raw_task(
           ^^^^^^^^^^^^^^
  File "/home/airflow/.local/lib/python3.12/site-packages/airflow/models/taskinstance.py", line 273, in _run_raw_task
    TaskInstance._execute_task_with_callbacks(
  File "/home/airflow/.local/lib/python3.12/site-packages/airflow/models/taskinstance.py", line 3158, in _execute_task_with_callbacks
    result = self._execute_task(context, task_orig)
             ^^^^^^^^^^^^^^^^^^^^^^^^^^^^^^^^^^^^^^
  File "/home/airflow/.local/lib/python3.12/site-packages/airflow/models/taskinstance.py", line 3182, in _execute_task
    return _execute_task(self, context, task_orig)
           ^^^^^^^^^^^^^^^^^^^^^^^^^^^^^^^^^^^^^^^
  File "/home/airflow/.local/lib/python3.12/site-packages/airflow/models/taskinstance.py", line 767, in _execute_task
    result = _execute_callable(context=context, **execute_callable_kwargs)
             ^^^^^^^^^^^^^^^^^^^^^^^^^^^^^^^^^^^^^^^^^^^^^^^^^^^^^^^^^^^^^
  File "/home/airflow/.local/lib/python3.12/site-packages/airflow/models/taskinstance.py", line 733, in _execute_callable
    return ExecutionCallableRunner(
           ^^^^^^^^^^^^^^^^^^^^^^^^
  File "/home/airflow/.local/lib/python3.12/site-packages/airflow/utils/operator_helpers.py", line 252, in run
    return self.func(*args, **kwargs)
           ^^^^^^^^^^^^^^^^^^^^^^^^^^
  File "/home/airflow/.local/lib/python3.12/site-packages/airflow/models/baseoperator.py", line 406, in wrapper
    return func(self, *args, **kwargs)
           ^^^^^^^^^^^^^^^^^^^^^^^^^^^
  File "/home/airflow/.local/lib/python3.12/site-packages/airflow/providers/docker/operators/docker.py", line 513, in execute
    return self._run_image()
           ^^^^^^^^^^^^^^^^^
  File "/home/airflow/.local/lib/python3.12/site-packages/airflow/providers/docker/operators/docker.py", line 372, in _run_image
    return self._run_image_with_mounts([*self.mounts, tmp_mount], add_tmp_variable=True)
           ^^^^^^^^^^^^^^^^^^^^^^^^^^^^^^^^^^^^^^^^^^^^^^^^^^^^^^^^^^^^^^^^^^^^^^^^^^^^^
  File "/home/airflow/.local/lib/python3.12/site-packages/airflow/providers/docker/operators/docker.py", line 446, in _run_image_with_mounts
    raise DockerContainerFailedException(f"Docker container failed: {result!r}", logs=log_lines)
airflow.providers.docker.exceptions.DockerContainerFailedException: Docker container failed: {'StatusCode': 1}
[2024-11-18T16:08:20.062+0000] {local_task_job_runner.py:266} INFO - Task exited with return code 1
[2024-11-18T16:08:20.087+0000] {taskinstance.py:3900} INFO - 0 downstream tasks scheduled from follow-on schedule check
[2024-11-18T16:08:20.090+0000] {local_task_job_runner.py:245} INFO - ::endgroup::
[2024-11-18T16:12:06.530+0000] {local_task_job_runner.py:123} INFO - ::group::Pre task execution logs
[2024-11-18T16:12:06.548+0000] {taskinstance.py:2612} INFO - Dependencies all met for dep_context=non-requeueable deps ti=<TaskInstance: Ciril_group.load_to_db scheduled__2024-11-17T00:00:00+00:00 [queued]>
[2024-11-18T16:12:06.556+0000] {taskinstance.py:2612} INFO - Dependencies all met for dep_context=requeueable deps ti=<TaskInstance: Ciril_group.load_to_db scheduled__2024-11-17T00:00:00+00:00 [queued]>
[2024-11-18T16:12:06.557+0000] {taskinstance.py:2865} INFO - Starting attempt 1 of 6
[2024-11-18T16:12:06.570+0000] {taskinstance.py:2888} INFO - Executing <Task(DockerOperator): load_to_db> on 2024-11-17 00:00:00+00:00
[2024-11-18T16:12:06.578+0000] {standard_task_runner.py:104} INFO - Running: ['***', 'tasks', 'run', 'Ciril_group', 'load_to_db', 'scheduled__2024-11-17T00:00:00+00:00', '--job-id', '7', '--raw', '--subdir', 'DAGS_FOLDER/ciril_group_dag.py', '--cfg-path', '/tmp/tmp6i82yq1h']
[2024-11-18T16:12:06.580+0000] {standard_task_runner.py:105} INFO - Job 7: Subtask load_to_db
[2024-11-18T16:12:06.581+0000] {logging_mixin.py:190} WARNING - /home/***/.local/lib/python3.12/site-packages/***/task/task_runner/standard_task_runner.py:70 DeprecationWarning: This process (pid=255) is multi-threaded, use of fork() may lead to deadlocks in the child.
[2024-11-18T16:12:06.582+0000] {standard_task_runner.py:72} INFO - Started process 257 to run task
[2024-11-18T16:12:06.621+0000] {task_command.py:467} INFO - Running <TaskInstance: Ciril_group.load_to_db scheduled__2024-11-17T00:00:00+00:00 [running]> on host 4aaa0084fcc4
[2024-11-18T16:12:06.690+0000] {taskinstance.py:3131} INFO - Exporting env vars: AIRFLOW_CTX_DAG_OWNER='Simo' AIRFLOW_CTX_DAG_ID='Ciril_group' AIRFLOW_CTX_TASK_ID='load_to_db' AIRFLOW_CTX_EXECUTION_DATE='2024-11-17T00:00:00+00:00' AIRFLOW_CTX_TRY_NUMBER='1' AIRFLOW_CTX_DAG_RUN_ID='scheduled__2024-11-17T00:00:00+00:00'
[2024-11-18T16:12:06.691+0000] {taskinstance.py:731} INFO - ::endgroup::
[2024-11-18T16:12:06.741+0000] {docker.py:367} INFO - Starting docker container from image ***_ciril:latest
[2024-11-18T16:12:14.326+0000] {docker.py:438} INFO - 
[2024-11-18T16:12:14.938+0000] {docker.py:438} INFO - /opt/***/load-csv/load_to_db.py:13: RemovedIn20Warning: [31mDeprecated API features detected! These feature(s) are not compatible with SQLAlchemy 2.0. [32mTo prevent incompatible upgrades prior to updating applications, ensure requirements files are pinned to "sqlalchemy<2.0". [36mSet environment variable SQLALCHEMY_WARN_20=1 to show all deprecation warnings.  Set environment variable SQLALCHEMY_SILENCE_UBER_WARNING=1 to silence this message.[0m (Background on SQLAlchemy 2.0 at: https://sqlalche.me/e/b8d9)
[2024-11-18T16:12:14.939+0000] {docker.py:438} INFO -   metadata = sqlalchemy.schema.MetaData(engine)
[2024-11-18T16:12:14.940+0000] {docker.py:438} INFO - Connexion Ã  la base de donnÃ©es rÃ©ussie
[2024-11-18T16:12:14.955+0000] {docker.py:438} INFO - Traceback (most recent call last):
[2024-11-18T16:12:14.956+0000] {docker.py:438} INFO -   File "/home/***/.local/lib/python3.12/site-packages/sqlalchemy/engine/base.py", line 1910, in _execute_context
[2024-11-18T16:12:14.957+0000] {docker.py:438} INFO - self.dialect.do_execute(
[2024-11-18T16:12:14.958+0000] {docker.py:438} INFO -   File "/home/***/.local/lib/python3.12/site-packages/sqlalchemy/engine/default.py", line 736, in do_execute
[2024-11-18T16:12:14.958+0000] {docker.py:438} INFO -     cursor.execute(statement, parameters)
[2024-11-18T16:12:14.959+0000] {docker.py:438} INFO -   File "/home/***/.local/lib/python3.12/site-packages/MySQLdb/cursors.py", line 206, in execute
[2024-11-18T16:12:14.959+0000] {docker.py:438} INFO -     res = self._query(query)
[2024-11-18T16:12:14.960+0000] {docker.py:438} INFO -           ^^^^^^^^^^^^^^^^^^
[2024-11-18T16:12:14.960+0000] {docker.py:438} INFO -   File "/home/***/.local/lib/python3.12/site-packages/MySQLdb/cursors.py", line 319, in _query
[2024-11-18T16:12:14.960+0000] {docker.py:438} INFO -     db.query(q)
[2024-11-18T16:12:14.961+0000] {docker.py:438} INFO -   File "/home/***/.local/lib/python3.12/site-packages/MySQLdb/connections.py", line 254, in query
[2024-11-18T16:12:14.962+0000] {docker.py:438} INFO -     _mysql.connection.query(self, query)
[2024-11-18T16:12:14.962+0000] {docker.py:438} INFO - MySQLdb.ProgrammingError: (1146, "Table 'db_dteng.places' doesn't exist")
[2024-11-18T16:12:14.963+0000] {docker.py:438} INFO - 
[2024-11-18T16:12:14.963+0000] {docker.py:438} INFO - The above exception was the direct cause of the following exception:
[2024-11-18T16:12:14.964+0000] {docker.py:438} INFO - 
[2024-11-18T16:12:14.964+0000] {docker.py:438} INFO - Traceback (most recent call last):
[2024-11-18T16:12:14.965+0000] {docker.py:438} INFO -   File "/home/***/.local/lib/python3.12/site-packages/sqlalchemy/dialects/mysql/base.py", line 3220, in _show_create_table
[2024-11-18T16:12:14.965+0000] {docker.py:438} INFO - ).exec_driver_sql(st)
[2024-11-18T16:12:14.966+0000] {docker.py:438} INFO -       ^^^^^^^^^^^^^^^^^^^
[2024-11-18T16:12:14.966+0000] {docker.py:438} INFO -   File "/home/***/.local/lib/python3.12/site-packages/sqlalchemy/engine/base.py", line 1770, in exec_driver_sql
[2024-11-18T16:12:14.967+0000] {docker.py:438} INFO -     return self._exec_driver_sql(
[2024-11-18T16:12:14.967+0000] {docker.py:438} INFO -            ^^^^^^^^^^^^^^^^^^^^^^
[2024-11-18T16:12:14.967+0000] {docker.py:438} INFO -   File "/home/***/.local/lib/python3.12/site-packages/sqlalchemy/engine/base.py", line 1674, in _exec_driver_sql
[2024-11-18T16:12:14.968+0000] {docker.py:438} INFO -     ret = self._execute_context(
[2024-11-18T16:12:14.968+0000] {docker.py:438} INFO -           ^^^^^^^^^^^^^^^^^^^^^^
[2024-11-18T16:12:14.969+0000] {docker.py:438} INFO -   File "/home/***/.local/lib/python3.12/site-packages/sqlalchemy/engine/base.py", line 1953, in _execute_context
[2024-11-18T16:12:14.970+0000] {docker.py:438} INFO -     self._handle_dbapi_exception(
[2024-11-18T16:12:14.970+0000] {docker.py:438} INFO -   File "/home/***/.local/lib/python3.12/site-packages/sqlalchemy/engine/base.py", line 2134, in _handle_dbapi_exception
[2024-11-18T16:12:14.971+0000] {docker.py:438} INFO -     util.raise_(
[2024-11-18T16:12:14.971+0000] {docker.py:438} INFO -   File "/home/***/.local/lib/python3.12/site-packages/sqlalchemy/util/compat.py", line 211, in raise_
[2024-11-18T16:12:14.972+0000] {docker.py:438} INFO -     raise exception
[2024-11-18T16:12:14.972+0000] {docker.py:438} INFO -   File "/home/***/.local/lib/python3.12/site-packages/sqlalchemy/engine/base.py", line 1910, in _execute_context
[2024-11-18T16:12:14.973+0000] {docker.py:438} INFO -     self.dialect.do_execute(
[2024-11-18T16:12:14.973+0000] {docker.py:438} INFO -   File "/home/***/.local/lib/python3.12/site-packages/sqlalchemy/engine/default.py", line 736, in do_execute
[2024-11-18T16:12:14.974+0000] {docker.py:438} INFO -     cursor.execute(statement, parameters)
[2024-11-18T16:12:14.974+0000] {docker.py:438} INFO -   File "/home/***/.local/lib/python3.12/site-packages/MySQLdb/cursors.py", line 206, in execute
[2024-11-18T16:12:14.975+0000] {docker.py:438} INFO -     res = self._query(query)
[2024-11-18T16:12:14.975+0000] {docker.py:438} INFO -           ^^^^^^^^^^^^^^^^^^
[2024-11-18T16:12:14.976+0000] {docker.py:438} INFO -   File "/home/***/.local/lib/python3.12/site-packages/MySQLdb/cursors.py", line 319, in _query
[2024-11-18T16:12:14.976+0000] {docker.py:438} INFO -     db.query(q)
[2024-11-18T16:12:14.977+0000] {docker.py:438} INFO -   File "/home/***/.local/lib/python3.12/site-packages/MySQLdb/connections.py", line 254, in query
[2024-11-18T16:12:14.977+0000] {docker.py:438} INFO -     _mysql.connection.query(self, query)
[2024-11-18T16:12:14.978+0000] {docker.py:438} INFO - sqlalchemy.exc.ProgrammingError: (MySQLdb.ProgrammingError) (1146, "Table 'db_dteng.places' doesn't exist")
[2024-11-18T16:12:14.978+0000] {docker.py:438} INFO - [SQL: SHOW CREATE TABLE `places`]
[2024-11-18T16:12:14.978+0000] {docker.py:438} INFO - (Background on this error at: https://sqlalche.me/e/14/f405)
[2024-11-18T16:12:14.979+0000] {docker.py:438} INFO - 
[2024-11-18T16:12:14.979+0000] {docker.py:438} INFO - The above exception was the direct cause of the following exception:
[2024-11-18T16:12:14.980+0000] {docker.py:438} INFO - 
[2024-11-18T16:12:14.980+0000] {docker.py:438} INFO - Traceback (most recent call last):
[2024-11-18T16:12:14.981+0000] {docker.py:438} INFO -   File "/opt/***/load-csv/load_to_db.py", line 23, in <module>
[2024-11-18T16:12:14.981+0000] {docker.py:438} INFO -     Places=   sqlalchemy.schema.Table('places', metadata, autoload=True, autoload_with=engine)
[2024-11-18T16:12:14.982+0000] {docker.py:438} INFO -               ^^^^^^^^^^^^^^^^^^^^^^^^^^^^^^^^^^^^^^^^^^^^^^^^^^^^^^^^^^^^^^^^^^^^^^^^^^^^^^^^
[2024-11-18T16:12:14.982+0000] {docker.py:438} INFO -   File "<string>", line 2, in __new__
[2024-11-18T16:12:14.983+0000] {docker.py:438} INFO -   File "/home/***/.local/lib/python3.12/site-packages/sqlalchemy/util/deprecations.py", line 375, in warned
[2024-11-18T16:12:14.983+0000] {docker.py:438} INFO -     return fn(*args, **kwargs)
[2024-11-18T16:12:14.984+0000] {docker.py:438} INFO -            ^^^^^^^^^^^^^^^^^^^
[2024-11-18T16:12:14.984+0000] {docker.py:438} INFO -   File "/home/***/.local/lib/python3.12/site-packages/sqlalchemy/sql/schema.py", line 618, in __new__
[2024-11-18T16:12:14.985+0000] {docker.py:438} INFO -     with util.safe_reraise():
[2024-11-18T16:12:14.985+0000] {docker.py:438} INFO -          ^^^^^^^^^^^^^^^^^^^
[2024-11-18T16:12:14.986+0000] {docker.py:438} INFO -   File "/home/***/.local/lib/python3.12/site-packages/sqlalchemy/util/langhelpers.py", line 70, in __exit__
[2024-11-18T16:12:14.986+0000] {docker.py:438} INFO -     compat.raise_(
[2024-11-18T16:12:14.987+0000] {docker.py:438} INFO -   File "/home/***/.local/lib/python3.12/site-packages/sqlalchemy/util/compat.py", line 211, in raise_
[2024-11-18T16:12:14.987+0000] {docker.py:438} INFO -     raise exception
[2024-11-18T16:12:14.988+0000] {docker.py:438} INFO -   File "/home/***/.local/lib/python3.12/site-packages/sqlalchemy/sql/schema.py", line 614, in __new__
[2024-11-18T16:12:14.988+0000] {docker.py:438} INFO -     table._init(name, metadata, *args, **kw)
[2024-11-18T16:12:14.989+0000] {docker.py:438} INFO -   File "/home/***/.local/lib/python3.12/site-packages/sqlalchemy/sql/schema.py", line 689, in _init
[2024-11-18T16:12:14.989+0000] {docker.py:438} INFO -     self._autoload(
[2024-11-18T16:12:14.989+0000] {docker.py:438} INFO -   File "/home/***/.local/lib/python3.12/site-packages/sqlalchemy/sql/schema.py", line 724, in _autoload
[2024-11-18T16:12:14.990+0000] {docker.py:438} INFO -     conn_insp.reflect_table(
[2024-11-18T16:12:14.991+0000] {docker.py:438} INFO -   File "/home/***/.local/lib/python3.12/site-packages/sqlalchemy/engine/reflection.py", line 757, in reflect_table
[2024-11-18T16:12:14.991+0000] {docker.py:438} INFO -     tbl_opts = self.get_table_options(
[2024-11-18T16:12:14.991+0000] {docker.py:438} INFO -                ^^^^^^^^^^^^^^^^^^^^^^^
[2024-11-18T16:12:14.992+0000] {docker.py:438} INFO -   File "/home/***/.local/lib/python3.12/site-packages/sqlalchemy/engine/reflection.py", line 398, in get_table_options
[2024-11-18T16:12:14.992+0000] {docker.py:438} INFO -     return self.dialect.get_table_options(
[2024-11-18T16:12:14.993+0000] {docker.py:438} INFO -            ^^^^^^^^^^^^^^^^^^^^^^^^^^^^^^^
[2024-11-18T16:12:14.993+0000] {docker.py:438} INFO -   File "<string>", line 2, in get_table_options
[2024-11-18T16:12:14.993+0000] {docker.py:438} INFO -   File "/home/***/.local/lib/python3.12/site-packages/sqlalchemy/engine/reflection.py", line 55, in cache
[2024-11-18T16:12:14.994+0000] {docker.py:438} INFO -     ret = fn(self, con, *args, **kw)
[2024-11-18T16:12:14.994+0000] {docker.py:438} INFO -           ^^^^^^^^^^^^^^^^^^^^^^^^^^
[2024-11-18T16:12:14.994+0000] {docker.py:438} INFO -   File "/home/***/.local/lib/python3.12/site-packages/sqlalchemy/dialects/mysql/base.py", line 2828, in get_table_options
[2024-11-18T16:12:14.995+0000] {docker.py:438} INFO - parsed_state = self._parsed_state_or_create(
[2024-11-18T16:12:14.995+0000] {docker.py:438} INFO -                    ^^^^^^^^^^^^^^^^^^^^^^^^^^^^^
[2024-11-18T16:12:14.995+0000] {docker.py:438} INFO -   File "/home/***/.local/lib/python3.12/site-packages/sqlalchemy/dialects/mysql/base.py", line 3085, in _parsed_state_or_create
[2024-11-18T16:12:14.996+0000] {docker.py:438} INFO -     return self._setup_parser(
[2024-11-18T16:12:14.996+0000] {docker.py:438} INFO -            ^^^^^^^^^^^^^^^^^^^
[2024-11-18T16:12:14.996+0000] {docker.py:438} INFO -   File "<string>", line 2, in _setup_parser
[2024-11-18T16:12:14.997+0000] {docker.py:438} INFO -   File "/home/***/.local/lib/python3.12/site-packages/sqlalchemy/engine/reflection.py", line 55, in cache
[2024-11-18T16:12:14.997+0000] {docker.py:438} INFO -     ret = fn(self, con, *args, **kw)
[2024-11-18T16:12:14.997+0000] {docker.py:438} INFO -           ^^^^^^^^^^^^^^^^^^^^^^^^^^
[2024-11-18T16:12:14.998+0000] {docker.py:438} INFO -   File "/home/***/.local/lib/python3.12/site-packages/sqlalchemy/dialects/mysql/base.py", line 3112, in _setup_parser
[2024-11-18T16:12:14.998+0000] {docker.py:438} INFO -     sql = self._show_create_table(
[2024-11-18T16:12:14.999+0000] {docker.py:438} INFO -           ^^^^^^^^^^^^^^^^^^^^^^^^
[2024-11-18T16:12:14.999+0000] {docker.py:438} INFO -   File "/home/***/.local/lib/python3.12/site-packages/sqlalchemy/dialects/mysql/base.py", line 3223, in _show_create_table
[2024-11-18T16:12:14.999+0000] {docker.py:438} INFO -     util.raise_(exc.NoSuchTableError(full_name), replace_context=e)
[2024-11-18T16:12:15.000+0000] {docker.py:438} INFO -   File "/home/***/.local/lib/python3.12/site-packages/sqlalchemy/util/compat.py", line 211, in raise_
[2024-11-18T16:12:15.000+0000] {docker.py:438} INFO -     raise exception
[2024-11-18T16:12:15.000+0000] {docker.py:438} INFO - sqlalchemy.exc.NoSuchTableError: `places`
[2024-11-18T16:12:15.654+0000] {taskinstance.py:3310} ERROR - Task failed with exception
Traceback (most recent call last):
  File "/home/airflow/.local/lib/python3.12/site-packages/airflow/models/taskinstance.py", line 767, in _execute_task
    result = _execute_callable(context=context, **execute_callable_kwargs)
             ^^^^^^^^^^^^^^^^^^^^^^^^^^^^^^^^^^^^^^^^^^^^^^^^^^^^^^^^^^^^^
  File "/home/airflow/.local/lib/python3.12/site-packages/airflow/models/taskinstance.py", line 733, in _execute_callable
    return ExecutionCallableRunner(
           ^^^^^^^^^^^^^^^^^^^^^^^^
  File "/home/airflow/.local/lib/python3.12/site-packages/airflow/utils/operator_helpers.py", line 252, in run
    return self.func(*args, **kwargs)
           ^^^^^^^^^^^^^^^^^^^^^^^^^^
  File "/home/airflow/.local/lib/python3.12/site-packages/airflow/models/baseoperator.py", line 406, in wrapper
    return func(self, *args, **kwargs)
           ^^^^^^^^^^^^^^^^^^^^^^^^^^^
  File "/home/airflow/.local/lib/python3.12/site-packages/airflow/providers/docker/operators/docker.py", line 513, in execute
    return self._run_image()
           ^^^^^^^^^^^^^^^^^
  File "/home/airflow/.local/lib/python3.12/site-packages/airflow/providers/docker/operators/docker.py", line 372, in _run_image
    return self._run_image_with_mounts([*self.mounts, tmp_mount], add_tmp_variable=True)
           ^^^^^^^^^^^^^^^^^^^^^^^^^^^^^^^^^^^^^^^^^^^^^^^^^^^^^^^^^^^^^^^^^^^^^^^^^^^^^
  File "/home/airflow/.local/lib/python3.12/site-packages/airflow/providers/docker/operators/docker.py", line 446, in _run_image_with_mounts
    raise DockerContainerFailedException(f"Docker container failed: {result!r}", logs=log_lines)
airflow.providers.docker.exceptions.DockerContainerFailedException: Docker container failed: {'StatusCode': 1}
[2024-11-18T16:12:15.661+0000] {taskinstance.py:1225} INFO - Marking task as UP_FOR_RETRY. dag_id=Ciril_group, task_id=load_to_db, run_id=scheduled__2024-11-17T00:00:00+00:00, execution_date=20241117T000000, start_date=20241118T161206, end_date=20241118T161215
[2024-11-18T16:12:15.676+0000] {taskinstance.py:340} INFO - ::group::Post task execution logs
[2024-11-18T16:12:15.677+0000] {standard_task_runner.py:124} ERROR - Failed to execute job 7 for task load_to_db (Docker container failed: {'StatusCode': 1}; 257)
Traceback (most recent call last):
  File "/home/airflow/.local/lib/python3.12/site-packages/airflow/task/task_runner/standard_task_runner.py", line 117, in _start_by_fork
    ret = args.func(args, dag=self.dag)
          ^^^^^^^^^^^^^^^^^^^^^^^^^^^^^
  File "/home/airflow/.local/lib/python3.12/site-packages/airflow/cli/cli_config.py", line 49, in command
    return func(*args, **kwargs)
           ^^^^^^^^^^^^^^^^^^^^^
  File "/home/airflow/.local/lib/python3.12/site-packages/airflow/utils/cli.py", line 115, in wrapper
    return f(*args, **kwargs)
           ^^^^^^^^^^^^^^^^^^
  File "/home/airflow/.local/lib/python3.12/site-packages/airflow/cli/commands/task_command.py", line 483, in task_run
    task_return_code = _run_task_by_selected_method(args, _dag, ti)
                       ^^^^^^^^^^^^^^^^^^^^^^^^^^^^^^^^^^^^^^^^^^^^
  File "/home/airflow/.local/lib/python3.12/site-packages/airflow/cli/commands/task_command.py", line 256, in _run_task_by_selected_method
    return _run_raw_task(args, ti)
           ^^^^^^^^^^^^^^^^^^^^^^^
  File "/home/airflow/.local/lib/python3.12/site-packages/airflow/cli/commands/task_command.py", line 341, in _run_raw_task
    return ti._run_raw_task(
           ^^^^^^^^^^^^^^^^^
  File "/home/airflow/.local/lib/python3.12/site-packages/airflow/utils/session.py", line 97, in wrapper
    return func(*args, session=session, **kwargs)
           ^^^^^^^^^^^^^^^^^^^^^^^^^^^^^^^^^^^^^^
  File "/home/airflow/.local/lib/python3.12/site-packages/airflow/models/taskinstance.py", line 3004, in _run_raw_task
    return _run_raw_task(
           ^^^^^^^^^^^^^^
  File "/home/airflow/.local/lib/python3.12/site-packages/airflow/models/taskinstance.py", line 273, in _run_raw_task
    TaskInstance._execute_task_with_callbacks(
  File "/home/airflow/.local/lib/python3.12/site-packages/airflow/models/taskinstance.py", line 3158, in _execute_task_with_callbacks
    result = self._execute_task(context, task_orig)
             ^^^^^^^^^^^^^^^^^^^^^^^^^^^^^^^^^^^^^^
  File "/home/airflow/.local/lib/python3.12/site-packages/airflow/models/taskinstance.py", line 3182, in _execute_task
    return _execute_task(self, context, task_orig)
           ^^^^^^^^^^^^^^^^^^^^^^^^^^^^^^^^^^^^^^^
  File "/home/airflow/.local/lib/python3.12/site-packages/airflow/models/taskinstance.py", line 767, in _execute_task
    result = _execute_callable(context=context, **execute_callable_kwargs)
             ^^^^^^^^^^^^^^^^^^^^^^^^^^^^^^^^^^^^^^^^^^^^^^^^^^^^^^^^^^^^^
  File "/home/airflow/.local/lib/python3.12/site-packages/airflow/models/taskinstance.py", line 733, in _execute_callable
    return ExecutionCallableRunner(
           ^^^^^^^^^^^^^^^^^^^^^^^^
  File "/home/airflow/.local/lib/python3.12/site-packages/airflow/utils/operator_helpers.py", line 252, in run
    return self.func(*args, **kwargs)
           ^^^^^^^^^^^^^^^^^^^^^^^^^^
  File "/home/airflow/.local/lib/python3.12/site-packages/airflow/models/baseoperator.py", line 406, in wrapper
    return func(self, *args, **kwargs)
           ^^^^^^^^^^^^^^^^^^^^^^^^^^^
  File "/home/airflow/.local/lib/python3.12/site-packages/airflow/providers/docker/operators/docker.py", line 513, in execute
    return self._run_image()
           ^^^^^^^^^^^^^^^^^
  File "/home/airflow/.local/lib/python3.12/site-packages/airflow/providers/docker/operators/docker.py", line 372, in _run_image
    return self._run_image_with_mounts([*self.mounts, tmp_mount], add_tmp_variable=True)
           ^^^^^^^^^^^^^^^^^^^^^^^^^^^^^^^^^^^^^^^^^^^^^^^^^^^^^^^^^^^^^^^^^^^^^^^^^^^^^
  File "/home/airflow/.local/lib/python3.12/site-packages/airflow/providers/docker/operators/docker.py", line 446, in _run_image_with_mounts
    raise DockerContainerFailedException(f"Docker container failed: {result!r}", logs=log_lines)
airflow.providers.docker.exceptions.DockerContainerFailedException: Docker container failed: {'StatusCode': 1}
[2024-11-18T16:12:15.708+0000] {local_task_job_runner.py:266} INFO - Task exited with return code 1
[2024-11-18T16:12:15.726+0000] {taskinstance.py:3900} INFO - 0 downstream tasks scheduled from follow-on schedule check
[2024-11-18T16:12:15.728+0000] {local_task_job_runner.py:245} INFO - ::endgroup::
[2024-11-18T16:23:12.242+0000] {local_task_job_runner.py:123} INFO - ::group::Pre task execution logs
[2024-11-18T16:23:12.259+0000] {taskinstance.py:2612} INFO - Dependencies all met for dep_context=non-requeueable deps ti=<TaskInstance: Ciril_group.load_to_db scheduled__2024-11-17T00:00:00+00:00 [queued]>
[2024-11-18T16:23:12.268+0000] {taskinstance.py:2612} INFO - Dependencies all met for dep_context=requeueable deps ti=<TaskInstance: Ciril_group.load_to_db scheduled__2024-11-17T00:00:00+00:00 [queued]>
[2024-11-18T16:23:12.268+0000] {taskinstance.py:2865} INFO - Starting attempt 1 of 6
[2024-11-18T16:23:12.283+0000] {taskinstance.py:2888} INFO - Executing <Task(DockerOperator): load_to_db> on 2024-11-17 00:00:00+00:00
[2024-11-18T16:23:12.292+0000] {standard_task_runner.py:104} INFO - Running: ['***', 'tasks', 'run', 'Ciril_group', 'load_to_db', 'scheduled__2024-11-17T00:00:00+00:00', '--job-id', '8', '--raw', '--subdir', 'DAGS_FOLDER/ciril_group_dag.py', '--cfg-path', '/tmp/tmpg4lpdxgz']
[2024-11-18T16:23:12.295+0000] {standard_task_runner.py:105} INFO - Job 8: Subtask load_to_db
[2024-11-18T16:23:12.296+0000] {logging_mixin.py:190} WARNING - /home/***/.local/lib/python3.12/site-packages/***/task/task_runner/standard_task_runner.py:70 DeprecationWarning: This process (pid=242) is multi-threaded, use of fork() may lead to deadlocks in the child.
[2024-11-18T16:23:12.297+0000] {standard_task_runner.py:72} INFO - Started process 244 to run task
[2024-11-18T16:23:12.335+0000] {task_command.py:467} INFO - Running <TaskInstance: Ciril_group.load_to_db scheduled__2024-11-17T00:00:00+00:00 [running]> on host 0ae2d7ed9877
[2024-11-18T16:23:12.399+0000] {taskinstance.py:3131} INFO - Exporting env vars: AIRFLOW_CTX_DAG_OWNER='Simo' AIRFLOW_CTX_DAG_ID='Ciril_group' AIRFLOW_CTX_TASK_ID='load_to_db' AIRFLOW_CTX_EXECUTION_DATE='2024-11-17T00:00:00+00:00' AIRFLOW_CTX_TRY_NUMBER='1' AIRFLOW_CTX_DAG_RUN_ID='scheduled__2024-11-17T00:00:00+00:00'
[2024-11-18T16:23:12.400+0000] {taskinstance.py:731} INFO - ::endgroup::
[2024-11-18T16:23:12.441+0000] {docker.py:367} INFO - Starting docker container from image ***_ciril:latest
[2024-11-18T16:23:19.587+0000] {docker.py:438} INFO - 
[2024-11-18T16:23:20.190+0000] {docker.py:438} INFO - /opt/***/load-csv/load_to_db.py:13: RemovedIn20Warning: [31mDeprecated API features detected! These feature(s) are not compatible with SQLAlchemy 2.0. [32mTo prevent incompatible upgrades prior to updating applications, ensure requirements files are pinned to "sqlalchemy<2.0". [36mSet environment variable SQLALCHEMY_WARN_20=1 to show all deprecation warnings.  Set environment variable SQLALCHEMY_SILENCE_UBER_WARNING=1 to silence this message.[0m (Background on SQLAlchemy 2.0 at: https://sqlalche.me/e/b8d9)
[2024-11-18T16:23:20.191+0000] {docker.py:438} INFO -   metadata = sqlalchemy.schema.MetaData(engine)
[2024-11-18T16:23:20.191+0000] {docker.py:438} INFO - Connexion Ã  la base de donnÃ©es rÃ©ussie
[2024-11-18T16:23:20.200+0000] {docker.py:438} INFO - Traceback (most recent call last):
[2024-11-18T16:23:20.201+0000] {docker.py:438} INFO -   File "/home/***/.local/lib/python3.12/site-packages/sqlalchemy/engine/base.py", line 1910, in _execute_context
[2024-11-18T16:23:20.202+0000] {docker.py:438} INFO - self.dialect.do_execute(
[2024-11-18T16:23:20.202+0000] {docker.py:438} INFO -   File "/home/***/.local/lib/python3.12/site-packages/sqlalchemy/engine/default.py", line 736, in do_execute
[2024-11-18T16:23:20.203+0000] {docker.py:438} INFO -     cursor.execute(statement, parameters)
[2024-11-18T16:23:20.203+0000] {docker.py:438} INFO -   File "/home/***/.local/lib/python3.12/site-packages/MySQLdb/cursors.py", line 206, in execute
[2024-11-18T16:23:20.204+0000] {docker.py:438} INFO -     res = self._query(query)
[2024-11-18T16:23:20.204+0000] {docker.py:438} INFO -           ^^^^^^^^^^^^^^^^^^
[2024-11-18T16:23:20.205+0000] {docker.py:438} INFO -   File "/home/***/.local/lib/python3.12/site-packages/MySQLdb/cursors.py", line 319, in _query
[2024-11-18T16:23:20.205+0000] {docker.py:438} INFO -     db.query(q)
[2024-11-18T16:23:20.206+0000] {docker.py:438} INFO -   File "/home/***/.local/lib/python3.12/site-packages/MySQLdb/connections.py", line 254, in query
[2024-11-18T16:23:20.207+0000] {docker.py:438} INFO -     _mysql.connection.query(self, query)
[2024-11-18T16:23:20.207+0000] {docker.py:438} INFO - MySQLdb.ProgrammingError: (1146, "Table 'db_dteng.places' doesn't exist")
[2024-11-18T16:23:20.208+0000] {docker.py:438} INFO - 
[2024-11-18T16:23:20.208+0000] {docker.py:438} INFO - The above exception was the direct cause of the following exception:
[2024-11-18T16:23:20.209+0000] {docker.py:438} INFO - 
[2024-11-18T16:23:20.209+0000] {docker.py:438} INFO - Traceback (most recent call last):
[2024-11-18T16:23:20.209+0000] {docker.py:438} INFO -   File "/home/***/.local/lib/python3.12/site-packages/sqlalchemy/dialects/mysql/base.py", line 3220, in _show_create_table
[2024-11-18T16:23:20.210+0000] {docker.py:438} INFO - ).exec_driver_sql(st)
[2024-11-18T16:23:20.210+0000] {docker.py:438} INFO -       ^^^^^^^^^^^^^^^^^^^
[2024-11-18T16:23:20.211+0000] {docker.py:438} INFO -   File "/home/***/.local/lib/python3.12/site-packages/sqlalchemy/engine/base.py", line 1770, in exec_driver_sql
[2024-11-18T16:23:20.211+0000] {docker.py:438} INFO -     return self._exec_driver_sql(
[2024-11-18T16:23:20.212+0000] {docker.py:438} INFO -            ^^^^^^^^^^^^^^^^^^^^^^
[2024-11-18T16:23:20.212+0000] {docker.py:438} INFO -   File "/home/***/.local/lib/python3.12/site-packages/sqlalchemy/engine/base.py", line 1674, in _exec_driver_sql
[2024-11-18T16:23:20.213+0000] {docker.py:438} INFO -     ret = self._execute_context(
[2024-11-18T16:23:20.213+0000] {docker.py:438} INFO -           ^^^^^^^^^^^^^^^^^^^^^^
[2024-11-18T16:23:20.213+0000] {docker.py:438} INFO -   File "/home/***/.local/lib/python3.12/site-packages/sqlalchemy/engine/base.py", line 1953, in _execute_context
[2024-11-18T16:23:20.213+0000] {docker.py:438} INFO -     self._handle_dbapi_exception(
[2024-11-18T16:23:20.214+0000] {docker.py:438} INFO -   File "/home/***/.local/lib/python3.12/site-packages/sqlalchemy/engine/base.py", line 2134, in _handle_dbapi_exception
[2024-11-18T16:23:20.214+0000] {docker.py:438} INFO -     util.raise_(
[2024-11-18T16:23:20.215+0000] {docker.py:438} INFO -   File "/home/***/.local/lib/python3.12/site-packages/sqlalchemy/util/compat.py", line 211, in raise_
[2024-11-18T16:23:20.215+0000] {docker.py:438} INFO -     raise exception
[2024-11-18T16:23:20.215+0000] {docker.py:438} INFO -   File "/home/***/.local/lib/python3.12/site-packages/sqlalchemy/engine/base.py", line 1910, in _execute_context
[2024-11-18T16:23:20.216+0000] {docker.py:438} INFO -     self.dialect.do_execute(
[2024-11-18T16:23:20.216+0000] {docker.py:438} INFO -   File "/home/***/.local/lib/python3.12/site-packages/sqlalchemy/engine/default.py", line 736, in do_execute
[2024-11-18T16:23:20.216+0000] {docker.py:438} INFO -     cursor.execute(statement, parameters)
[2024-11-18T16:23:20.217+0000] {docker.py:438} INFO -   File "/home/***/.local/lib/python3.12/site-packages/MySQLdb/cursors.py", line 206, in execute
[2024-11-18T16:23:20.217+0000] {docker.py:438} INFO -     res = self._query(query)
[2024-11-18T16:23:20.217+0000] {docker.py:438} INFO -           ^^^^^^^^^^^^^^^^^^
[2024-11-18T16:23:20.218+0000] {docker.py:438} INFO -   File "/home/***/.local/lib/python3.12/site-packages/MySQLdb/cursors.py", line 319, in _query
[2024-11-18T16:23:20.218+0000] {docker.py:438} INFO -     db.query(q)
[2024-11-18T16:23:20.218+0000] {docker.py:438} INFO -   File "/home/***/.local/lib/python3.12/site-packages/MySQLdb/connections.py", line 254, in query
[2024-11-18T16:23:20.219+0000] {docker.py:438} INFO -     _mysql.connection.query(self, query)
[2024-11-18T16:23:20.219+0000] {docker.py:438} INFO - sqlalchemy.exc.ProgrammingError: (MySQLdb.ProgrammingError) (1146, "Table 'db_dteng.places' doesn't exist")
[2024-11-18T16:23:20.219+0000] {docker.py:438} INFO - [SQL: SHOW CREATE TABLE `places`]
[2024-11-18T16:23:20.220+0000] {docker.py:438} INFO - (Background on this error at: https://sqlalche.me/e/14/f405)
[2024-11-18T16:23:20.220+0000] {docker.py:438} INFO - 
[2024-11-18T16:23:20.220+0000] {docker.py:438} INFO - The above exception was the direct cause of the following exception:
[2024-11-18T16:23:20.221+0000] {docker.py:438} INFO - 
[2024-11-18T16:23:20.221+0000] {docker.py:438} INFO - Traceback (most recent call last):
[2024-11-18T16:23:20.221+0000] {docker.py:438} INFO -   File "/opt/***/load-csv/load_to_db.py", line 23, in <module>
[2024-11-18T16:23:20.222+0000] {docker.py:438} INFO -     Places=   sqlalchemy.schema.Table('places', metadata, autoload=True, autoload_with=engine)
[2024-11-18T16:23:20.222+0000] {docker.py:438} INFO -               ^^^^^^^^^^^^^^^^^^^^^^^^^^^^^^^^^^^^^^^^^^^^^^^^^^^^^^^^^^^^^^^^^^^^^^^^^^^^^^^^
[2024-11-18T16:23:20.222+0000] {docker.py:438} INFO -   File "<string>", line 2, in __new__
[2024-11-18T16:23:20.223+0000] {docker.py:438} INFO -   File "/home/***/.local/lib/python3.12/site-packages/sqlalchemy/util/deprecations.py", line 375, in warned
[2024-11-18T16:23:20.223+0000] {docker.py:438} INFO -     return fn(*args, **kwargs)
[2024-11-18T16:23:20.223+0000] {docker.py:438} INFO -            ^^^^^^^^^^^^^^^^^^^
[2024-11-18T16:23:20.224+0000] {docker.py:438} INFO -   File "/home/***/.local/lib/python3.12/site-packages/sqlalchemy/sql/schema.py", line 618, in __new__
[2024-11-18T16:23:20.224+0000] {docker.py:438} INFO -     with util.safe_reraise():
[2024-11-18T16:23:20.224+0000] {docker.py:438} INFO -          ^^^^^^^^^^^^^^^^^^^
[2024-11-18T16:23:20.225+0000] {docker.py:438} INFO -   File "/home/***/.local/lib/python3.12/site-packages/sqlalchemy/util/langhelpers.py", line 70, in __exit__
[2024-11-18T16:23:20.225+0000] {docker.py:438} INFO -     compat.raise_(
[2024-11-18T16:23:20.225+0000] {docker.py:438} INFO -   File "/home/***/.local/lib/python3.12/site-packages/sqlalchemy/util/compat.py", line 211, in raise_
[2024-11-18T16:23:20.226+0000] {docker.py:438} INFO -     raise exception
[2024-11-18T16:23:20.226+0000] {docker.py:438} INFO -   File "/home/***/.local/lib/python3.12/site-packages/sqlalchemy/sql/schema.py", line 614, in __new__
[2024-11-18T16:23:20.226+0000] {docker.py:438} INFO -     table._init(name, metadata, *args, **kw)
[2024-11-18T16:23:20.227+0000] {docker.py:438} INFO -   File "/home/***/.local/lib/python3.12/site-packages/sqlalchemy/sql/schema.py", line 689, in _init
[2024-11-18T16:23:20.227+0000] {docker.py:438} INFO -     self._autoload(
[2024-11-18T16:23:20.228+0000] {docker.py:438} INFO -   File "/home/***/.local/lib/python3.12/site-packages/sqlalchemy/sql/schema.py", line 724, in _autoload
[2024-11-18T16:23:20.228+0000] {docker.py:438} INFO -     conn_insp.reflect_table(
[2024-11-18T16:23:20.228+0000] {docker.py:438} INFO -   File "/home/***/.local/lib/python3.12/site-packages/sqlalchemy/engine/reflection.py", line 757, in reflect_table
[2024-11-18T16:23:20.229+0000] {docker.py:438} INFO -     tbl_opts = self.get_table_options(
[2024-11-18T16:23:20.229+0000] {docker.py:438} INFO -                ^^^^^^^^^^^^^^^^^^^^^^^
[2024-11-18T16:23:20.229+0000] {docker.py:438} INFO -   File "/home/***/.local/lib/python3.12/site-packages/sqlalchemy/engine/reflection.py", line 398, in get_table_options
[2024-11-18T16:23:20.230+0000] {docker.py:438} INFO -     return self.dialect.get_table_options(
[2024-11-18T16:23:20.230+0000] {docker.py:438} INFO -            ^^^^^^^^^^^^^^^^^^^^^^^^^^^^^^^
[2024-11-18T16:23:20.230+0000] {docker.py:438} INFO -   File "<string>", line 2, in get_table_options
[2024-11-18T16:23:20.231+0000] {docker.py:438} INFO -   File "/home/***/.local/lib/python3.12/site-packages/sqlalchemy/engine/reflection.py", line 55, in cache
[2024-11-18T16:23:20.231+0000] {docker.py:438} INFO -     ret = fn(self, con, *args, **kw)
[2024-11-18T16:23:20.231+0000] {docker.py:438} INFO -           ^^^^^^^^^^^^^^^^^^^^^^^^^^
[2024-11-18T16:23:20.232+0000] {docker.py:438} INFO -   File "/home/***/.local/lib/python3.12/site-packages/sqlalchemy/dialects/mysql/base.py", line 2828, in get_table_options
[2024-11-18T16:23:20.232+0000] {docker.py:438} INFO -     parsed_state = self._parsed_state_or_create(
[2024-11-18T16:23:20.232+0000] {docker.py:438} INFO -                    ^^^^^^^^^^^^^^^^^^^^^^^^^^^^^
[2024-11-18T16:23:20.232+0000] {docker.py:438} INFO -   F
[2024-11-18T16:23:20.233+0000] {docker.py:438} INFO - ile "/home/***/.local/lib/python3.12/site-packages/sqlalchemy/dialects/mysql/base.py", line 3085, in _parsed_state_or_create
[2024-11-18T16:23:20.233+0000] {docker.py:438} INFO -     return self._setup_parser(
[2024-11-18T16:23:20.233+0000] {docker.py:438} INFO -            ^^^^^^^^^^^^^^^^^^^
[2024-11-18T16:23:20.234+0000] {docker.py:438} INFO -   File "<string>", line 2, in _setup_parser
[2024-11-18T16:23:20.234+0000] {docker.py:438} INFO -   File "/home/***/.local/lib/python3.12/site-packages/sqlalchemy/engine/reflection.py", line 55, in cache
[2024-11-18T16:23:20.234+0000] {docker.py:438} INFO -     ret = fn(self, con, *args, **kw)
[2024-11-18T16:23:20.235+0000] {docker.py:438} INFO -           ^^^^^^^^^^^^^^^^^^^^^^^^^^
[2024-11-18T16:23:20.235+0000] {docker.py:438} INFO -   File "/home/***/.local/lib/python3.12/site-packages/sqlalchemy/dialects/mysql/base.py", line 3112, in _setup_parser
[2024-11-18T16:23:20.235+0000] {docker.py:438} INFO -     sql = self._show_create_table(
[2024-11-18T16:23:20.236+0000] {docker.py:438} INFO -           ^^^^^^^^^^^^^^^^^^^^^^^^
[2024-11-18T16:23:20.236+0000] {docker.py:438} INFO -   File "/home/***/.local/lib/python3.12/site-packages/sqlalchemy/dialects/mysql/base.py", line 3223, in _show_create_table
[2024-11-18T16:23:20.236+0000] {docker.py:438} INFO -     util.raise_(exc.NoSuchTableError(full_name), replace_context=e)
[2024-11-18T16:23:20.237+0000] {docker.py:438} INFO -   File "/home/***/.local/lib/python3.12/site-packages/sqlalchemy/util/compat.py", line 211, in raise_
[2024-11-18T16:23:20.237+0000] {docker.py:438} INFO -     raise exception
[2024-11-18T16:23:20.238+0000] {docker.py:438} INFO - sqlalchemy.exc.NoSuchTableError: `places`
[2024-11-18T16:23:20.873+0000] {taskinstance.py:3310} ERROR - Task failed with exception
Traceback (most recent call last):
  File "/home/airflow/.local/lib/python3.12/site-packages/airflow/models/taskinstance.py", line 767, in _execute_task
    result = _execute_callable(context=context, **execute_callable_kwargs)
             ^^^^^^^^^^^^^^^^^^^^^^^^^^^^^^^^^^^^^^^^^^^^^^^^^^^^^^^^^^^^^
  File "/home/airflow/.local/lib/python3.12/site-packages/airflow/models/taskinstance.py", line 733, in _execute_callable
    return ExecutionCallableRunner(
           ^^^^^^^^^^^^^^^^^^^^^^^^
  File "/home/airflow/.local/lib/python3.12/site-packages/airflow/utils/operator_helpers.py", line 252, in run
    return self.func(*args, **kwargs)
           ^^^^^^^^^^^^^^^^^^^^^^^^^^
  File "/home/airflow/.local/lib/python3.12/site-packages/airflow/models/baseoperator.py", line 406, in wrapper
    return func(self, *args, **kwargs)
           ^^^^^^^^^^^^^^^^^^^^^^^^^^^
  File "/home/airflow/.local/lib/python3.12/site-packages/airflow/providers/docker/operators/docker.py", line 513, in execute
    return self._run_image()
           ^^^^^^^^^^^^^^^^^
  File "/home/airflow/.local/lib/python3.12/site-packages/airflow/providers/docker/operators/docker.py", line 372, in _run_image
    return self._run_image_with_mounts([*self.mounts, tmp_mount], add_tmp_variable=True)
           ^^^^^^^^^^^^^^^^^^^^^^^^^^^^^^^^^^^^^^^^^^^^^^^^^^^^^^^^^^^^^^^^^^^^^^^^^^^^^
  File "/home/airflow/.local/lib/python3.12/site-packages/airflow/providers/docker/operators/docker.py", line 446, in _run_image_with_mounts
    raise DockerContainerFailedException(f"Docker container failed: {result!r}", logs=log_lines)
airflow.providers.docker.exceptions.DockerContainerFailedException: Docker container failed: {'StatusCode': 1}
[2024-11-18T16:23:20.880+0000] {taskinstance.py:1225} INFO - Marking task as UP_FOR_RETRY. dag_id=Ciril_group, task_id=load_to_db, run_id=scheduled__2024-11-17T00:00:00+00:00, execution_date=20241117T000000, start_date=20241118T162312, end_date=20241118T162320
[2024-11-18T16:23:20.895+0000] {taskinstance.py:340} INFO - ::group::Post task execution logs
[2024-11-18T16:23:20.896+0000] {standard_task_runner.py:124} ERROR - Failed to execute job 8 for task load_to_db (Docker container failed: {'StatusCode': 1}; 244)
Traceback (most recent call last):
  File "/home/airflow/.local/lib/python3.12/site-packages/airflow/task/task_runner/standard_task_runner.py", line 117, in _start_by_fork
    ret = args.func(args, dag=self.dag)
          ^^^^^^^^^^^^^^^^^^^^^^^^^^^^^
  File "/home/airflow/.local/lib/python3.12/site-packages/airflow/cli/cli_config.py", line 49, in command
    return func(*args, **kwargs)
           ^^^^^^^^^^^^^^^^^^^^^
  File "/home/airflow/.local/lib/python3.12/site-packages/airflow/utils/cli.py", line 115, in wrapper
    return f(*args, **kwargs)
           ^^^^^^^^^^^^^^^^^^
  File "/home/airflow/.local/lib/python3.12/site-packages/airflow/cli/commands/task_command.py", line 483, in task_run
    task_return_code = _run_task_by_selected_method(args, _dag, ti)
                       ^^^^^^^^^^^^^^^^^^^^^^^^^^^^^^^^^^^^^^^^^^^^
  File "/home/airflow/.local/lib/python3.12/site-packages/airflow/cli/commands/task_command.py", line 256, in _run_task_by_selected_method
    return _run_raw_task(args, ti)
           ^^^^^^^^^^^^^^^^^^^^^^^
  File "/home/airflow/.local/lib/python3.12/site-packages/airflow/cli/commands/task_command.py", line 341, in _run_raw_task
    return ti._run_raw_task(
           ^^^^^^^^^^^^^^^^^
  File "/home/airflow/.local/lib/python3.12/site-packages/airflow/utils/session.py", line 97, in wrapper
    return func(*args, session=session, **kwargs)
           ^^^^^^^^^^^^^^^^^^^^^^^^^^^^^^^^^^^^^^
  File "/home/airflow/.local/lib/python3.12/site-packages/airflow/models/taskinstance.py", line 3004, in _run_raw_task
    return _run_raw_task(
           ^^^^^^^^^^^^^^
  File "/home/airflow/.local/lib/python3.12/site-packages/airflow/models/taskinstance.py", line 273, in _run_raw_task
    TaskInstance._execute_task_with_callbacks(
  File "/home/airflow/.local/lib/python3.12/site-packages/airflow/models/taskinstance.py", line 3158, in _execute_task_with_callbacks
    result = self._execute_task(context, task_orig)
             ^^^^^^^^^^^^^^^^^^^^^^^^^^^^^^^^^^^^^^
  File "/home/airflow/.local/lib/python3.12/site-packages/airflow/models/taskinstance.py", line 3182, in _execute_task
    return _execute_task(self, context, task_orig)
           ^^^^^^^^^^^^^^^^^^^^^^^^^^^^^^^^^^^^^^^
  File "/home/airflow/.local/lib/python3.12/site-packages/airflow/models/taskinstance.py", line 767, in _execute_task
    result = _execute_callable(context=context, **execute_callable_kwargs)
             ^^^^^^^^^^^^^^^^^^^^^^^^^^^^^^^^^^^^^^^^^^^^^^^^^^^^^^^^^^^^^
  File "/home/airflow/.local/lib/python3.12/site-packages/airflow/models/taskinstance.py", line 733, in _execute_callable
    return ExecutionCallableRunner(
           ^^^^^^^^^^^^^^^^^^^^^^^^
  File "/home/airflow/.local/lib/python3.12/site-packages/airflow/utils/operator_helpers.py", line 252, in run
    return self.func(*args, **kwargs)
           ^^^^^^^^^^^^^^^^^^^^^^^^^^
  File "/home/airflow/.local/lib/python3.12/site-packages/airflow/models/baseoperator.py", line 406, in wrapper
    return func(self, *args, **kwargs)
           ^^^^^^^^^^^^^^^^^^^^^^^^^^^
  File "/home/airflow/.local/lib/python3.12/site-packages/airflow/providers/docker/operators/docker.py", line 513, in execute
    return self._run_image()
           ^^^^^^^^^^^^^^^^^
  File "/home/airflow/.local/lib/python3.12/site-packages/airflow/providers/docker/operators/docker.py", line 372, in _run_image
    return self._run_image_with_mounts([*self.mounts, tmp_mount], add_tmp_variable=True)
           ^^^^^^^^^^^^^^^^^^^^^^^^^^^^^^^^^^^^^^^^^^^^^^^^^^^^^^^^^^^^^^^^^^^^^^^^^^^^^
  File "/home/airflow/.local/lib/python3.12/site-packages/airflow/providers/docker/operators/docker.py", line 446, in _run_image_with_mounts
    raise DockerContainerFailedException(f"Docker container failed: {result!r}", logs=log_lines)
airflow.providers.docker.exceptions.DockerContainerFailedException: Docker container failed: {'StatusCode': 1}
[2024-11-18T16:23:20.931+0000] {local_task_job_runner.py:266} INFO - Task exited with return code 1
[2024-11-18T16:23:20.949+0000] {taskinstance.py:3900} INFO - 0 downstream tasks scheduled from follow-on schedule check
[2024-11-18T16:23:20.951+0000] {local_task_job_runner.py:245} INFO - ::endgroup::
[2024-11-18T16:27:02.286+0000] {local_task_job_runner.py:123} INFO - ::group::Pre task execution logs
[2024-11-18T16:27:02.302+0000] {taskinstance.py:2612} INFO - Dependencies all met for dep_context=non-requeueable deps ti=<TaskInstance: Ciril_group.load_to_db scheduled__2024-11-17T00:00:00+00:00 [queued]>
[2024-11-18T16:27:02.310+0000] {taskinstance.py:2612} INFO - Dependencies all met for dep_context=requeueable deps ti=<TaskInstance: Ciril_group.load_to_db scheduled__2024-11-17T00:00:00+00:00 [queued]>
[2024-11-18T16:27:02.311+0000] {taskinstance.py:2865} INFO - Starting attempt 1 of 6
[2024-11-18T16:27:02.325+0000] {taskinstance.py:2888} INFO - Executing <Task(DockerOperator): load_to_db> on 2024-11-17 00:00:00+00:00
[2024-11-18T16:27:02.331+0000] {standard_task_runner.py:104} INFO - Running: ['***', 'tasks', 'run', 'Ciril_group', 'load_to_db', 'scheduled__2024-11-17T00:00:00+00:00', '--job-id', '7', '--raw', '--subdir', 'DAGS_FOLDER/ciril_group_dag.py', '--cfg-path', '/tmp/tmpmahetqew']
[2024-11-18T16:27:02.333+0000] {standard_task_runner.py:105} INFO - Job 7: Subtask load_to_db
[2024-11-18T16:27:02.336+0000] {logging_mixin.py:190} WARNING - /home/***/.local/lib/python3.12/site-packages/***/task/task_runner/standard_task_runner.py:70 DeprecationWarning: This process (pid=264) is multi-threaded, use of fork() may lead to deadlocks in the child.
[2024-11-18T16:27:02.337+0000] {standard_task_runner.py:72} INFO - Started process 265 to run task
[2024-11-18T16:27:02.372+0000] {task_command.py:467} INFO - Running <TaskInstance: Ciril_group.load_to_db scheduled__2024-11-17T00:00:00+00:00 [running]> on host 061dbc9e53b1
[2024-11-18T16:27:02.447+0000] {taskinstance.py:3131} INFO - Exporting env vars: AIRFLOW_CTX_DAG_OWNER='Simo' AIRFLOW_CTX_DAG_ID='Ciril_group' AIRFLOW_CTX_TASK_ID='load_to_db' AIRFLOW_CTX_EXECUTION_DATE='2024-11-17T00:00:00+00:00' AIRFLOW_CTX_TRY_NUMBER='1' AIRFLOW_CTX_DAG_RUN_ID='scheduled__2024-11-17T00:00:00+00:00'
[2024-11-18T16:27:02.448+0000] {taskinstance.py:731} INFO - ::endgroup::
[2024-11-18T16:27:02.495+0000] {docker.py:367} INFO - Starting docker container from image ***_ciril:latest
[2024-11-18T16:27:10.002+0000] {docker.py:438} INFO - 
[2024-11-18T16:27:10.586+0000] {docker.py:438} INFO - /opt/***/load-csv/load_to_db.py:13: RemovedIn20Warning: [31mDeprecated API features detected! These feature(s) are not compatible with SQLAlchemy 2.0. [32mTo prevent incompatible upgrades prior to updating applications, ensure requirements files are pinned to "sqlalchemy<2.0". [36mSet environment variable SQLALCHEMY_WARN_20=1 to show all deprecation warnings.  Set environment variable SQLALCHEMY_SILENCE_UBER_WARNING=1 to silence this message.[0m (Background on SQLAlchemy 2.0 at: https://sqlalche.me/e/b8d9)
[2024-11-18T16:27:10.587+0000] {docker.py:438} INFO -   metadata = sqlalchemy.schema.MetaData(engine)
[2024-11-18T16:27:10.587+0000] {docker.py:438} INFO - Connexion Ã  la base de donnÃ©es rÃ©ussie
[2024-11-18T16:27:10.602+0000] {docker.py:438} INFO - Fichier people.csv introuvable.
[2024-11-18T16:27:10.603+0000] {docker.py:438} INFO - Fichier places.csv introuvable.
[2024-11-18T16:27:11.257+0000] {taskinstance.py:340} INFO - ::group::Post task execution logs
[2024-11-18T16:27:11.258+0000] {taskinstance.py:352} INFO - Marking task as SUCCESS. dag_id=Ciril_group, task_id=load_to_db, run_id=scheduled__2024-11-17T00:00:00+00:00, execution_date=20241117T000000, start_date=20241118T162702, end_date=20241118T162711
[2024-11-18T16:27:11.290+0000] {local_task_job_runner.py:266} INFO - Task exited with return code 0
[2024-11-18T16:27:11.308+0000] {taskinstance.py:3900} INFO - 1 downstream tasks scheduled from follow-on schedule check
[2024-11-18T16:27:11.310+0000] {local_task_job_runner.py:245} INFO - ::endgroup::
[2024-11-18T16:48:43.844+0000] {local_task_job_runner.py:123} INFO - ::group::Pre task execution logs
[2024-11-18T16:48:43.860+0000] {taskinstance.py:2612} INFO - Dependencies all met for dep_context=non-requeueable deps ti=<TaskInstance: Ciril_group.load_to_db scheduled__2024-11-17T00:00:00+00:00 [queued]>
[2024-11-18T16:48:43.868+0000] {taskinstance.py:2612} INFO - Dependencies all met for dep_context=requeueable deps ti=<TaskInstance: Ciril_group.load_to_db scheduled__2024-11-17T00:00:00+00:00 [queued]>
[2024-11-18T16:48:43.868+0000] {taskinstance.py:2865} INFO - Starting attempt 1 of 6
[2024-11-18T16:48:43.881+0000] {taskinstance.py:2888} INFO - Executing <Task(DockerOperator): load_to_db> on 2024-11-17 00:00:00+00:00
[2024-11-18T16:48:43.890+0000] {standard_task_runner.py:104} INFO - Running: ['***', 'tasks', 'run', 'Ciril_group', 'load_to_db', 'scheduled__2024-11-17T00:00:00+00:00', '--job-id', '7', '--raw', '--subdir', 'DAGS_FOLDER/ciril_group_dag.py', '--cfg-path', '/tmp/tmpm8i37b3i']
[2024-11-18T16:48:43.892+0000] {logging_mixin.py:190} WARNING - /home/***/.local/lib/python3.12/site-packages/***/task/task_runner/standard_task_runner.py:70 DeprecationWarning: This process (pid=243) is multi-threaded, use of fork() may lead to deadlocks in the child.
[2024-11-18T16:48:43.892+0000] {standard_task_runner.py:105} INFO - Job 7: Subtask load_to_db
[2024-11-18T16:48:43.892+0000] {standard_task_runner.py:72} INFO - Started process 245 to run task
[2024-11-18T16:48:43.928+0000] {task_command.py:467} INFO - Running <TaskInstance: Ciril_group.load_to_db scheduled__2024-11-17T00:00:00+00:00 [running]> on host 7171e7af8d4a
[2024-11-18T16:48:43.992+0000] {taskinstance.py:3131} INFO - Exporting env vars: AIRFLOW_CTX_DAG_OWNER='Simo' AIRFLOW_CTX_DAG_ID='Ciril_group' AIRFLOW_CTX_TASK_ID='load_to_db' AIRFLOW_CTX_EXECUTION_DATE='2024-11-17T00:00:00+00:00' AIRFLOW_CTX_TRY_NUMBER='1' AIRFLOW_CTX_DAG_RUN_ID='scheduled__2024-11-17T00:00:00+00:00'
[2024-11-18T16:48:43.993+0000] {taskinstance.py:731} INFO - ::endgroup::
[2024-11-18T16:48:44.036+0000] {docker.py:367} INFO - Starting docker container from image ***_ciril:latest
[2024-11-18T16:48:51.660+0000] {docker.py:438} INFO - 
[2024-11-18T16:48:52.246+0000] {docker.py:438} INFO - /opt/***/load-csv/load_to_db.py:13: RemovedIn20Warning: [31mDeprecated API features detected! These feature(s) are not compatible with SQLAlchemy 2.0. [32mTo prevent incompatible upgrades prior to updating applications, ensure requirements files are pinned to "sqlalchemy<2.0". [36mSet environment variable SQLALCHEMY_WARN_20=1 to show all deprecation warnings.  Set environment variable SQLALCHEMY_SILENCE_UBER_WARNING=1 to silence this message.[0m (Background on SQLAlchemy 2.0 at: https://sqlalche.me/e/b8d9)
[2024-11-18T16:48:52.247+0000] {docker.py:438} INFO -   metadata = sqlalchemy.schema.MetaData(engine)
[2024-11-18T16:48:52.248+0000] {docker.py:438} INFO - Connexion Ã  la base de donnÃ©es rÃ©ussie
[2024-11-18T16:48:52.260+0000] {docker.py:438} INFO - Fichier people.csv introuvable.
[2024-11-18T16:48:52.261+0000] {docker.py:438} INFO - Fichier places.csv introuvable.
[2024-11-18T16:48:52.886+0000] {taskinstance.py:340} INFO - ::group::Post task execution logs
[2024-11-18T16:48:52.887+0000] {taskinstance.py:352} INFO - Marking task as SUCCESS. dag_id=Ciril_group, task_id=load_to_db, run_id=scheduled__2024-11-17T00:00:00+00:00, execution_date=20241117T000000, start_date=20241118T164843, end_date=20241118T164852
[2024-11-18T16:48:52.928+0000] {local_task_job_runner.py:266} INFO - Task exited with return code 0
[2024-11-18T16:48:52.945+0000] {taskinstance.py:3900} INFO - 1 downstream tasks scheduled from follow-on schedule check
[2024-11-18T16:48:52.947+0000] {local_task_job_runner.py:245} INFO - ::endgroup::
